Workbook

Sheet Read me
A1: RRG Website Shipping · Australia · proposed rates with a Bulky size
A2: Prepared 20 October 2026 from Roof Racks Galore order and carrier data. Same layout as "RRG Website Shipping OCT 2025": one tab per delivery state, a table for each warehouse the order ships from, Standard and Priority, Metro / Metro Outer / Regional.
A4: Settings (change the yellow cells; every price in the workbook updates)
A5: Freight margin on top of expected cost | B5: 0 | C5: 0% = break-even: on average the Standard charge covers what the carrier charges us for that size, zone and warehouse. 10% adds 10% on top of expected cost.
A6: Minimum Priority uplift over Standard ($) | B6: 5 | C6: Priority is at least this much more than Standard.
A7: Round prices up to the next $x.50 up to ($) | B7: 30 | C7: Below this, prices end in .50 (e.g. $12.50). Above it they round up to the next $5.
A9: Priority ÷ Standard ratio by size
A10: Small | B10: 1.34 | C10: Median of Priority ÷ Standard across the 2025 sheet, kept between 1.20 and 1.35 (Large was 2.1 and XL 1.0 in 2025 because those Standard prices were far below cost). Applied to every cell. Change these if you want a different Priority premium.
A11: Medium | B11: 1.26
A12: Large | B12: 1.35
A13: XL | B13: 1.2
A14: XXL | B14: 1.2
A15: Bulky | B15: 1.2
A17: How the prices are set
A18: 1. Each order is sized the way the website does it: every product gets a 1–5 score from its longest side, cubic weight (250 kg/m³) and actual weight, and the order takes its biggest product's size. See the Freight SIZE RULES tab.
A19: 2. Expected cost = what carriers actually charged us (invoiced cost, or the carrier estimate where not yet billed, plus 10% GST) on 5,882 matched orders, June–October 2026, that went as one invoice in one shipment.
A20: 3. Costs are averaged after dropping the top and bottom 10% of orders in each group, so one-off surcharges don't set the price.
A21: 4. Each size × zone gets a national figure, separately for same-state and interstate deliveries. Each warehouse-to-state lane then gets a factor from its own orders (for example WA to VIC costs about 25% more than the interstate average). Lanes with few orders lean on the national figure; lanes with no orders use distance.
A22: 5. Where a lane has its own orders for a size and zone, those orders are blended in. Prices never go down from a smaller size to a larger one, or from Metro to Outer to Regional.
A23: 6. Standard = expected cost × (1 + freight margin), rounded up. Priority = Standard × the Priority ratio for its size (above), at least the minimum uplift, rounded up. We don't yet have enough priority shipments to cost Priority separately.
A24: 7. Delivery time frames are copied from the 2025 sheet, except that there is no 0–1 day Priority any more: those 30 cells (all same-state Metro deliveries) are now Priority 1–2 days and Standard 1–3 days (was 1–2 days).
A25: 8. One rate for interstate XXL and Bulky to Metro Outer and Regional: these have a single price, the Priority price, used for both Standard and Priority. Shown in the state tabs as the same figure in both tables (grey cells), and marked "One rate" on the Cost model tab.
A27: What else changed from the 2025 sheet
A28: • New Bulky size: any product of 0.4 m³ or more (cubic weight 100 kg+), such as roof boxes, rooftop tents, platforms, trays and ladders, is Bulky. Today those are charged as XL or XXL. Taking them out lowers XL and XXL, since Bulky orders cost about $190–$220 to send against about $125 for other XL and XXL orders. Bulky delivery times are copied from XXL.
A29: • The TAS tab now has a From SA table and the WA tab a From TAS table (both were missing).
... A38: • The Impact tab re-prices the same 5,882 orders under these rates so you can see the effect before changing the website.

Sheet Summary
A1: Summary
A2: Re-pricing the 5,882 matched single-shipment orders (Impact tab) under the new rates. Updates when you change the settings on Read me.
B4: Orders | C4: We charged | D4: Cost us | E4: Charged − cost | F4: New rates would charge | G4: New − cost
A5: All orders | B5: =COUNTA(Impact!$A$2:$A$5883) -> 5882 | C5: =SUM(Impact!$G$2:$G$5883) -> 114894.12 | D5: =SUM(Impact!$H$2:$H$5883) -> 240540.63 | E5: =C5-D5 -> -125646.51 | F5: =SUM(Impact!$J$2:$J$5883) -> 243385.5 | G5: =F5-D5 -> 2844.87
A7: By size
A8: Small | B8: =COUNTIF(Impact!$D$2:$D$5883,"Small") -> 2681 | C8: =SUMIF(Impact!$D$2:$D$5883,"Small",Impact!$G$2:$G$5883) -> 37442.65 | D8: =SUMIF(Impact!$D$2:$D$5883,"Small",Impact!$H$2:$H$5883) -> 38519.61 | E8: =C8-D8 -> -1076.96 | F8: =SUMIF(Impact!$D$2:$D$5883,"Small",Impact!$J$2:$J$5883) -> 37854.5 | G8: =F8-D8 -> -665.11
A9: Medium | B9: =COUNTIF(Impact!$D$2:$D$5883,"Medium") -> 2516 | C9: =SUMIF(Impact!$D$2:$D$5883,"Medium",Impact!$G$2:$G$5883) -> 40549.48 | D9: =SUMIF(Impact!$D$2:$D$5883,"Medium",Impact!$H$2:$H$5883) -> 111570.83 | E9: =C9-D9 -> -71021.35 | F9: =SUMIF(Impact!$D$2:$D$5883,"Medium",Impact!$J$2:$J$5883) -> 116496 | G9: =F9-D9 -> 4925.17
A10: Large | B10: =COUNTIF(Impact!$D$2:$D$5883,"Large") -> 346 | C10: =SUMIF(Impact!$D$2:$D$5883,"Large",Impact!$G$2:$G$5883) -> 12563 | D10: =SUMIF(Impact!$D$2:$D$5883,"Large",Impact!$H$2:$H$5883) -> 30449.77 | E10: =C10-D10 -> -17886.77 | F10: =SUMIF(Impact!$D$2:$D$5883,"Large",Impact!$J$2:$J$5883) -> 29545 | G10: =F10-D10 -> -904.77
A11: XL | B11: =COUNTIF(Impact!$D$2:$D$5883,"XL") -> 233 | C11: =SUMIF(Impact!$D$2:$D$5883,"XL",Impact!$G$2:$G$5883) -> 14564.99 | D11: =SUMIF(Impact!$D$2:$D$5883,"XL",Impact!$H$2:$H$5883) -> 36049.21 | E11: =C11-D11 -> -21484.22 | F11: =SUMIF(Impact!$D$2:$D$5883,"XL",Impact!$J$2:$J$5883) -> 35450 | G11: =F11-D11 -> -599.21
A12: XXL | B12: =COUNTIF(Impact!$D$2:$D$5883,"XXL") -> 25 | C12: =SUMIF(Impact!$D$2:$D$5883,"XXL",Impact!$G$2:$G$5883) -> 3130 | D12: =SUMIF(Impact!$D$2:$D$5883,"XXL",Impact!$H$2:$H$5883) -> 4413.05 | E12: =C12-D12 -> -1283.05 | F12: =SUMIF(Impact!$D$2:$D$5883,"XXL",Impact!$J$2:$J$5883) -> 4615 | G12: =F12-D12 -> 201.95
A13: Bulky | B13: =COUNTIF(Impact!$D$2:$D$5883,"Bulky") -> 81 | C13: =SUMIF(Impact!$D$2:$D$5883,"Bulky",Impact!$G$2:$G$5883) -> 6644 | D13: =SUMIF(Impact!$D$2:$D$5883,"Bulky",Impact!$H$2:$H$5883) -> 19538.16 | E13: =C13-D13 -> -12894.16 | F13: =SUMIF(Impact!$D$2:$D$5883,"Bulky",Impact!$J$2:$J$5883) -> 19425 | G13: =F13-D13 -> -113.16
A15: By zone
A16: Metro | B16: =COUNTIF(Impact!$C$2:$C$5883,"Metro") -> 2671 | C16: =SUMIF(Impact!$C$2:$C$5883,"Metro",Impact!$G$2:$G$5883) -> 39188.7 | D16: =SUMIF(Impact!$C$2:$C$5883,"Metro",Impact!$H$2:$H$5883) -> 84408.92 | E16: =C16-D16 -> -45220.22 | F16: =SUMIF(Impact!$C$2:$C$5883,"Metro",Impact!$J$2:$J$5883) -> 84518 | G16: =F16-D16 -> 109.08
A17: Metro Outer | B17: =COUNTIF(Impact!$C$2:$C$5883,"Metro Outer") -> 1750 | C17: =SUMIF(Impact!$C$2:$C$5883,"Metro Outer",Impact!$G$2:$G$5883) -> 32928.98 | D17: =SUMIF(Impact!$C$2:$C$5883,"Metro Outer",Impact!$H$2:$H$5883) -> 77446.75 | E17: =C17-D17 -> -44517.77 | F17: =SUMIF(Impact!$C$2:$C$5883,"Metro Outer",Impact!$J$2:$J$5883) -> 79702.5 | G17: =F17-D17 -> 2255.75
A18: Regional | B18: =COUNTIF(Impact!$C$2:$C$5883,"Regional") -> 1461 | C18: =SUMIF(Impact!$C$2:$C$5883,"Regional",Impact!$G$2:$G$5883) -> 42776.44 | D18: =SUMIF(Impact!$C$2:$C$5883,"Regional",Impact!$H$2:$H$5883) -> 78684.96 | E18: =C18-D18 -> -35908.52 | F18: =SUMIF(Impact!$C$2:$C$5883,"Regional",Impact!$J$2:$J$5883) -> 79165 | G18: =F18-D18 -> 480.04
A20: By warehouse
A21: QLD · Brendale | B21: =COUNTIF(Impact!$B$2:$B$5883,"QLD") -> 1636 | C21: =SUMIF(Impact!$B$2:$B$5883,"QLD",Impact!$G$2:$G$5883) -> 31332.63 | D21: =SUMIF(Impact!$B$2:$B$5883,"QLD",Impact!$H$2:$H$5883) -> 65008.7 | E21: =C21-D21 -> -33676.07 | F21: =SUMIF(Impact!$B$2:$B$5883,"QLD",Impact!$J$2:$J$5883) -> 66398.5 | G21: =F21-D21 -> 1389.8
A22: NSW · Moorebank | B22: =COUNTIF(Impact!$B$2:$B$5883,"NSW") -> 1735 | C22: =SUMIF(Impact!$B$2:$B$5883,"NSW",Impact!$G$2:$G$5883) -> 31503 | D22: =SUMIF(Impact!$B$2:$B$5883,"NSW",Impact!$H$2:$H$5883) -> 63242.37 | E22: =C22-D22 -> -31739.37 | F22: =SUMIF(Impact!$B$2:$B$5883,"NSW",Impact!$J$2:$J$5883) -> 64194 | G22: =F22-D22 -> 951.63
A23: VIC · Campbellfield | B23: =COUNTIF(Impact!$B$2:$B$5883,"VIC") -> 1154 | C23: =SUMIF(Impact!$B$2:$B$5883,"VIC",Impact!$G$2:$G$5883) -> 21504 | D23: =SUMIF(Impact!$B$2:$B$5883,"VIC",Impact!$H$2:$H$5883) -> 49083.33 | E23: =C23-D23 -> -27579.33 | F23: =SUMIF(Impact!$B$2:$B$5883,"VIC",Impact!$J$2:$J$5883) -> 50927.5 | G23: =F23-D23 -> 1844.17
A24: SA · Adelaide | B24: =COUNTIF(Impact!$B$2:$B$5883,"SA") -> 520 | C24: =SUMIF(Impact!$B$2:$B$5883,"SA",Impact!$G$2:$G$5883) -> 12112.99 | D24: =SUMIF(Impact!$B$2:$B$5883,"SA",Impact!$H$2:$H$5883) -> 21825.77 | E24: =C24-D24 -> -9712.78 | F24: =SUMIF(Impact!$B$2:$B$5883,"SA",Impact!$J$2:$J$5883) -> 23232.5 | G24: =F24-D24 -> 1406.73
A25: WA · Wangara | B25: =COUNTIF(Impact!$B$2:$B$5883,"WA") -> 599 | C25: =SUMIF(Impact!$B$2:$B$5883,"WA",Impact!$G$2:$G$5883) -> 13897 | D25: =SUMIF(Impact!$B$2:$B$5883,"WA",Impact!$H$2:$H$5883) -> 29455.45 | E25: =C25-D25 -> -15558.45 | F25: =SUMIF(Impact!$B$2:$B$5883,"WA",Impact!$J$2:$J$5883) -> 26758.5 | G25: =F25-D25 -> -2696.95
A26: TAS · Moonah | B26: =COUNTIF(Impact!$B$2:$B$5883,"TAS") -> 137 | C26: =SUMIF(Impact!$B$2:$B$5883,"TAS",Impact!$G$2:$G$5883) -> 2712 | D26: =SUMIF(Impact!$B$2:$B$5883,"TAS",Impact!$H$2:$H$5883) -> 7001.57 | E26: =C26-D26 -> -4289.57 | F26: =SUMIF(Impact!$B$2:$B$5883,"TAS",Impact!$J$2:$J$5883) -> 6360.5 | G26: =F26-D26 -> -641.07
A27: ACT · Fyshwick | B27: =COUNTIF(Impact!$B$2:$B$5883,"ACT") -> 101 | C27: =SUMIF(Impact!$B$2:$B$5883,"ACT",Impact!$G$2:$G$5883) -> 1832.5 | D27: =SUMIF(Impact!$B$2:$B$5883,"ACT",Impact!$H$2:$H$5883) -> 4923.44 | E27: =C27-D27 -> -3090.94 | F27: =SUMIF(Impact!$B$2:$B$5883,"ACT",Impact!$J$2:$J$5883) -> 5514 | G27: =F27-D27 -> 590.56
A29: Typical price per order, Standard (median of each tab's same-state table)
A30: Size | B30: Metro 2025 | C30: Metro new | D30: Outer 2025 | E30: Outer new | F30: Regional 2025 | G30: Regional new
A31: Small | B31: 9.5 | C31: =MEDIAN('Cost model'!M74,'Cost model'!M200,'Cost model'!M380,'Cost model'!M506,'Cost model'!M632,'Cost model'!M758,'Cost model'!M884) -> 8.5 | D31: 12.5 | E31: =MEDIAN('Cost model'!M75,'Cost model'!M201,'Cost model'!M381,'Cost model'!M507,'Cost model'!M633,'Cost model'!M759,'Cost model'!M885) -> 13.5 | F31: 17.5 | G31: =MEDIAN('Cost model'!M76,'Cost model'!M202,'Cost model'!M382,'Cost model'!M508,'Cost model'!M634,'Cost model'!M760,'Cost model'!M886) -> 18.5
A32: Medium | B32: 9.5 | C32: =MEDIAN('Cost model'!M77,'Cost model'!M203,'Cost model'!M383,'Cost model'!M509,'Cost model'!M635,'Cost model'!M761,'Cost model'!M887) -> 27.5 | D32: 12.5 | E32: =MEDIAN('Cost model'!M78,'Cost model'!M204,'Cost model'!M384,'Cost model'!M510,'Cost model'!M636,'Cost model'!M762,'Cost model'!M888) -> 45 | F32: 19.5 | G32: =MEDIAN('Cost model'!M79,'Cost model'!M205,'Cost model'!M385,'Cost model'!M511,'Cost model'!M637,'Cost model'!M763,'Cost model'!M889) -> 55
A33: Large | B33: 19 | C33: =MEDIAN('Cost model'!M80,'Cost model'!M206,'Cost model'!M386,'Cost model'!M512,'Cost model'!M638,'Cost model'!M764,'Cost model'!M890) -> 55 | D33: 24.5 | E33: =MEDIAN('Cost model'!M81,'Cost model'!M207,'Cost model'!M387,'Cost model'!M513,'Cost model'!M639,'Cost model'!M765,'Cost model'!M891) -> 75 | F33: 50 | G33: =MEDIAN('Cost model'!M82,'Cost model'!M208,'Cost model'!M388,'Cost model'!M514,'Cost model'!M640,'Cost model'!M766,'Cost model'!M892) -> 110
A34: XL | B34: 25 | C34: =MEDIAN('Cost model'!M83,'Cost model'!M209,'Cost model'!M389,'Cost model'!M515,'Cost model'!M641,'Cost model'!M767,'Cost model'!M893) -> 105 | D34: 45 | E34: =MEDIAN('Cost model'!M84,'Cost model'!M210,'Cost model'!M390,'Cost model'!M516,'Cost model'!M642,'Cost model'!M768,'Cost model'!M894) -> 135 | F34: 85 | G34: =MEDIAN('Cost model'!M85,'Cost model'!M211,'Cost model'!M391,'Cost model'!M517,'Cost model'!M643,'Cost model'!M769,'Cost model'!M895) -> 175
A35: XXL | B35: 45 | C35: =MEDIAN('Cost model'!M86,'Cost model'!M212,'Cost model'!M392,'Cost model'!M518,'Cost model'!M644,'Cost model'!M770,'Cost model'!M896) -> 125 | D35: 85 | E35: =MEDIAN('Cost model'!M87,'Cost model'!M213,'Cost model'!M393,'Cost model'!M519,'Cost model'!M645,'Cost model'!M771,'Cost model'!M897) -> 160 | F35: 250 | G35: =MEDIAN('Cost model'!M88,'Cost model'!M214,'Cost model'!M394,'Cost model'!M520,'Cost model'!M646,'Cost model'!M772,'Cost model'!M898) -> 250
A36: Bulky (XXL today) | B36: 45 | C36: =MEDIAN('Cost model'!M89,'Cost model'!M215,'Cost model'!M395,'Cost model'!M521,'Cost model'!M647,'Cost model'!M773,'Cost model'!M899) -> 135 | D36: 85 | E36: =MEDIAN('Cost model'!M90,'Cost model'!M216,'Cost model'!M396,'Cost model'!M522,'Cost model'!M648,'Cost model'!M774,'Cost model'!M900) -> 225 | F36: 250 | G36: =MEDIAN('Cost model'!M91,'Cost model'!M217,'Cost model'!M397,'Cost model'!M523,'Cost model'!M649,'Cost model'!M775,'Cost model'!M901) -> 295
A38: Option: split Medium at 1.05 m (what Medium orders actually cost us, incl. GST, trimmed average)
B39: Orders | C39: Metro | D39: Outer metro | E39: Regional
A40: Medium up to 1.05 m, same state | B40: 437 | C40: 11.22 | D40: 21.12 | E40: 30.7
A41: Medium over 1.05 m, same state | B41: 1356 | C41: 31.31 | D41: 50.16 | E41: 52.68
A42: Medium up to 1.05 m, interstate | B42: 189 | C42: 25.46 | D42: 30.96 | E42: 37.56
A43: Medium over 1.05 m, interstate | B43: 534 | C43: 55.99 | D43: 60.24 | E43: 66.2
A44: Most Medium orders under 1.05 m can go Australia Post. Splitting Medium would let the website keep a low price for those and charge the long ones what StarTrack costs. It needs a 6th size on the website, so it isn't applied in the state tabs.

Sheet ACT
A1: Freight Charges for ACT Orders
A3: Standard | B3: From QLD | F3: From VIC | J3: From SA | N3: From NSW | R3: From ACT | V3: From TAS | Z3: From WA
A4: Freight Size | B4: Metro | C4: Metro Outer | D4: Regional | F4: Metro | G4: Metro Outer | H4: Regional | J4: Metro | K4: Metro Outer | L4: Regional | N4: Metro | O4: Metro Outer | P4: Regional | R4: Metro | S4: Metro Outer | T4: Regional | V4: Metro | W4: Metro Outer | X4: Regional | Z4: Metro | AA4: Metro Outer | AB4: Regional
A5: Small | B5: ='Cost model'!M2 -> 14.5 | C5: ='Cost model'!M3 -> 14.5 | D5: ='Cost model'!M4 -> 19.5 | F5: ='Cost model'!M20 -> 13.5 | G5: ='Cost model'!M21 -> 15.5 | H5: ='Cost model'!M22 -> 19.5 | J5: ='Cost model'!M38 -> 13.5 | K5: ='Cost model'!M39 -> 14.5 | L5: ='Cost model'!M40 -> 19.5 | N5: ='Cost model'!M56 -> 11.5 | O5: ='Cost model'!M57 -> 13.5 | P5: ='Cost model'!M58 -> 18.5 | R5: ='Cost model'!M74 -> 21.5 | S5: ='Cost model'!M75 -> 35 | T5: ='Cost model'!M76 -> 40 | V5: ='Cost model'!M92 -> 13.5 | W5: ='Cost model'!M93 -> 15.5 | X5: ='Cost model'!M94 -> 20.5 | Z5: ='Cost model'!M110 -> 13.5 | AA5: ='Cost model'!M111 -> 16.5 | AB5: ='Cost model'!M112 -> 21.5
A6: Medium | B6: ='Cost model'!M5 -> 50 | C6: ='Cost model'!M6 -> 50 | D6: ='Cost model'!M7 -> 60 | F6: ='Cost model'!M23 -> 55 | G6: ='Cost model'!M24 -> 55 | H6: ='Cost model'!M25 -> 60 | J6: ='Cost model'!M41 -> 45 | K6: ='Cost model'!M42 -> 50 | L6: ='Cost model'!M43 -> 60 | N6: ='Cost model'!M59 -> 45 | O6: ='Cost model'!M60 -> 50 | P6: ='Cost model'!M61 -> 55 | R6: ='Cost model'!M77 -> 50 | S6: ='Cost model'!M78 -> 100 | T6: ='Cost model'!M79 -> 115 | V6: ='Cost model'!M95 -> 50 | W6: ='Cost model'!M96 -> 55 | X6: ='Cost model'!M97 -> 60 | Z6: ='Cost model'!M113 -> 50 | AA6: ='Cost model'!M114 -> 55 | AB6: ='Cost model'!M115 -> 65
A7: Large | B7: ='Cost model'!M8 -> 80 | C7: ='Cost model'!M9 -> 90 | D7: ='Cost model'!M10 -> 120 | F7: ='Cost model'!M26 -> 85 | G7: ='Cost model'!M27 -> 95 | H7: ='Cost model'!M28 -> 125 | J7: ='Cost model'!M44 -> 80 | K7: ='Cost model'!M45 -> 90 | L7: ='Cost model'!M46 -> 120 | N7: ='Cost model'!M62 -> 80 | O7: ='Cost model'!M63 -> 85 | P7: ='Cost model'!M64 -> 115 | R7: ='Cost model'!M80 -> 115 | S7: ='Cost model'!M81 -> 180 | T7: ='Cost model'!M82 -> 225 | V7: ='Cost model'!M98 -> 85 | W7: ='Cost model'!M99 -> 95 | X7: ='Cost model'!M100 -> 125 | Z7: ='Cost model'!M116 -> 90 | AA7: ='Cost model'!M117 -> 100 | AB7: ='Cost model'!M118 -> 130
A8: XL | B8: ='Cost model'!M11 -> 135 | C8: ='Cost model'!M12 -> 165 | D8: ='Cost model'!M13 -> 200 | F8: ='Cost model'!M29 -> 140 | G8: ='Cost model'!M30 -> 170 | H8: ='Cost model'!M31 -> 205 | J8: ='Cost model'!M47 -> 135 | K8: ='Cost model'!M48 -> 165 | L8: ='Cost model'!M49 -> 195 | N8: ='Cost model'!M65 -> 130 | O8: ='Cost model'!M66 -> 155 | P8: ='Cost model'!M67 -> 185 | R8: ='Cost model'!M83 -> 210 | S8: ='Cost model'!M84 -> 295 | T8: ='Cost model'!M85 -> 445 | V8: ='Cost model'!M101 -> 140 | W8: ='Cost model'!M102 -> 170 | X8: ='Cost model'!M103 -> 205 | Z8: ='Cost model'!M119 -> 150 | AA8: ='Cost model'!M120 -> 180 | AB8: ='Cost model'!M121 -> 215
A9: XXL | B9: ='Cost model'!M14 -> 175 | C9: ='Cost model'!M15 -> 260 | D9: ='Cost model'!M16 -> 310 | F9: ='Cost model'!M32 -> 180 | G9: ='Cost model'!M33 -> 265 | H9: ='Cost model'!M34 -> 320 | J9: ='Cost model'!M50 -> 175 | K9: ='Cost model'!M51 -> 260 | L9: ='Cost model'!M52 -> 310 | N9: ='Cost model'!M68 -> 165 | O9: ='Cost model'!M69 -> 240 | P9: ='Cost model'!M70 -> 290 | R9: ='Cost model'!M86 -> 265 | S9: ='Cost model'!M87 -> 380 | T9: ='Cost model'!M88 -> 565 | V9: ='Cost model'!M104 -> 180 | W9: ='Cost model'!M105 -> 265 | X9: ='Cost model'!M106 -> 320 | Z9: ='Cost model'!M122 -> 190 | AA9: ='Cost model'!M123 -> 285 | AB9: ='Cost model'!M124 -> 340
A10: Bulky | B10: ='Cost model'!M17 -> 240 | C10: ='Cost model'!M18 -> 375 | D10: ='Cost model'!M19 -> 435 | F10: ='Cost model'!M35 -> 245 | G10: ='Cost model'!M36 -> 380 | H10: ='Cost model'!M37 -> 445 | J10: ='Cost model'!M53 -> 240 | K10: ='Cost model'!M54 -> 370 | L10: ='Cost model'!M55 -> 435 | N10: ='Cost model'!M71 -> 225 | O10: ='Cost model'!M72 -> 350 | P10: ='Cost model'!M73 -> 410 | R10: ='Cost model'!M89 -> 290 | S10: ='Cost model'!M90 -> 520 | T10: ='Cost model'!M91 -> 680 | V10: ='Cost model'!M107 -> 250 | W10: ='Cost model'!M108 -> 385 | X10: ='Cost model'!M109 -> 450 | Z10: ='Cost model'!M125 -> 265 | AA10: ='Cost model'!M126 -> 410 | AB10: ='Cost model'!M127 -> 475
A12: Priority | B12: From QLD | F12: From VIC | J12: From SA | N12: From NSW | R12: From ACT | V12: From TAS | Z12: From WA
A13: Freight Size | B13: Metro | C13: Metro Outer | D13: Regional | F13: Metro | G13: Metro Outer | H13: Regional | J13: Metro | K13: Metro Outer | L13: Regional | N13: Metro | O13: Metro Outer | P13: Regional | R13: Metro | S13: Metro Outer | T13: Regional | V13: Metro | W13: Metro Outer | X13: Regional | Z13: Metro | AA13: Metro Outer | AB13: Regional
A14: Small | B14: ='Cost model'!N2 -> 19.5 | C14: ='Cost model'!N3 -> 19.5 | D14: ='Cost model'!N4 -> 26.5 | F14: ='Cost model'!N20 -> 18.5 | G14: ='Cost model'!N21 -> 21.5 | H14: ='Cost model'!N22 -> 26.5 | J14: ='Cost model'!N38 -> 18.5 | K14: ='Cost model'!N39 -> 19.5 | L14: ='Cost model'!N40 -> 26.5 | N14: ='Cost model'!N56 -> 16.5 | O14: ='Cost model'!N57 -> 18.5 | P14: ='Cost model'!N58 -> 25.5 | R14: ='Cost model'!N74 -> 29.5 | S14: ='Cost model'!N75 -> 50 | T14: ='Cost model'!N76 -> 55 | V14: ='Cost model'!N92 -> 18.5 | W14: ='Cost model'!N93 -> 21.5 | X14: ='Cost model'!N94 -> 27.5 | Z14: ='Cost model'!N110 -> 18.5 | AA14: ='Cost model'!N111 -> 22.5 | AB14: ='Cost model'!N112 -> 29.5
A15: Medium | B15: ='Cost model'!N5 -> 65 | C15: ='Cost model'!N6 -> 65 | D15: ='Cost model'!N7 -> 80 | F15: ='Cost model'!N23 -> 70 | G15: ='Cost model'!N24 -> 70 | H15: ='Cost model'!N25 -> 80 | J15: ='Cost model'!N41 -> 60 | K15: ='Cost model'!N42 -> 65 | L15: ='Cost model'!N43 -> 80 | N15: ='Cost model'!N59 -> 60 | O15: ='Cost model'!N60 -> 65 | P15: ='Cost model'!N61 -> 70 | R15: ='Cost model'!N77 -> 65 | S15: ='Cost model'!N78 -> 130 | T15: ='Cost model'!N79 -> 145 | V15: ='Cost model'!N95 -> 65 | W15: ='Cost model'!N96 -> 70 | X15: ='Cost model'!N97 -> 80 | Z15: ='Cost model'!N113 -> 65 | AA15: ='Cost model'!N114 -> 70 | AB15: ='Cost model'!N115 -> 85
A16: Large | B16: ='Cost model'!N8 -> 110 | C16: ='Cost model'!N9 -> 125 | D16: ='Cost model'!N10 -> 165 | F16: ='Cost model'!N26 -> 115 | G16: ='Cost model'!N27 -> 130 | H16: ='Cost model'!N28 -> 170 | J16: ='Cost model'!N44 -> 110 | K16: ='Cost model'!N45 -> 125 | L16: ='Cost model'!N46 -> 165 | N16: ='Cost model'!N62 -> 110 | O16: ='Cost model'!N63 -> 115 | P16: ='Cost model'!N64 -> 160 | R16: ='Cost model'!N80 -> 160 | S16: ='Cost model'!N81 -> 245 | T16: ='Cost model'!N82 -> 305 | V16: ='Cost model'!N98 -> 115 | W16: ='Cost model'!N99 -> 130 | X16: ='Cost model'!N100 -> 170 | Z16: ='Cost model'!N116 -> 125 | AA16: ='Cost model'!N117 -> 135 | AB16: ='Cost model'!N118 -> 180
A17: XL | B17: ='Cost model'!N11 -> 165 | C17: ='Cost model'!N12 -> 200 | D17: ='Cost model'!N13 -> 240 | F17: ='Cost model'!N29 -> 170 | G17: ='Cost model'!N30 -> 205 | H17: ='Cost model'!N31 -> 250 | J17: ='Cost model'!N47 -> 165 | K17: ='Cost model'!N48 -> 200 | L17: ='Cost model'!N49 -> 235 | N17: ='Cost model'!N65 -> 160 | O17: ='Cost model'!N66 -> 190 | P17: ='Cost model'!N67 -> 225 | R17: ='Cost model'!N83 -> 255 | S17: ='Cost model'!N84 -> 355 | T17: ='Cost model'!N85 -> 535 | V17: ='Cost model'!N101 -> 170 | W17: ='Cost model'!N102 -> 205 | X17: ='Cost model'!N103 -> 250 | Z17: ='Cost model'!N119 -> 180 | AA17: ='Cost model'!N120 -> 220 | AB17: ='Cost model'!N121 -> 260
A18: XXL | B18: ='Cost model'!N14 -> 210 | C18: ='Cost model'!N15 -> 260 | D18: ='Cost model'!N16 -> 310 | F18: ='Cost model'!N32 -> 220 | G18: ='Cost model'!N33 -> 265 | H18: ='Cost model'!N34 -> 320 | J18: ='Cost model'!N50 -> 210 | K18: ='Cost model'!N51 -> 260 | L18: ='Cost model'!N52 -> 310 | N18: ='Cost model'!N68 -> 200 | O18: ='Cost model'!N69 -> 240 | P18: ='Cost model'!N70 -> 290 | R18: ='Cost model'!N86 -> 320 | S18: ='Cost model'!N87 -> 460 | T18: ='Cost model'!N88 -> 680 | V18: ='Cost model'!N104 -> 220 | W18: ='Cost model'!N105 -> 265 | X18: ='Cost model'!N106 -> 320 | Z18: ='Cost model'!N122 -> 230 | AA18: ='Cost model'!N123 -> 285 | AB18: ='Cost model'!N124 -> 340
A19: Bulky | B19: ='Cost model'!N17 -> 290 | C19: ='Cost model'!N18 -> 375 | D19: ='Cost model'!N19 -> 435 | F19: ='Cost model'!N35 -> 295 | G19: ='Cost model'!N36 -> 380 | H19: ='Cost model'!N37 -> 445 | J19: ='Cost model'!N53 -> 290 | K19: ='Cost model'!N54 -> 370 | L19: ='Cost model'!N55 -> 435 | N19: ='Cost model'!N71 -> 270 | O19: ='Cost model'!N72 -> 350 | P19: ='Cost model'!N73 -> 410 | R19: ='Cost model'!N89 -> 350 | S19: ='Cost model'!N90 -> 625 | T19: ='Cost model'!N91 -> 820 | V19: ='Cost model'!N107 -> 300 | W19: ='Cost model'!N108 -> 385 | X19: ='Cost model'!N109 -> 450 | Z19: ='Cost model'!N125 -> 320 | AA19: ='Cost model'!N126 -> 410 | AB19: ='Cost model'!N127 -> 475
A21: Delivery time frames for ACT Orders
A23: Standard | B23: From QLD | F23: From VIC | J23: From SA | N23: From NSW | R23: From ACT | V23: From TAS | Z23: From WA
A24: Freight Size | B24: Metro | C24: Metro Outer | D24: Regional | F24: Metro | G24: Metro Outer | H24: Regional | J24: Metro | K24: Metro Outer | L24: Regional | N24: Metro | O24: Metro Outer | P24: Regional | R24: Metro | S24: Metro Outer | T24: Regional | V24: Metro | W24: Metro Outer | X24: Regional | Z24: Metro | AA24: Metro Outer | AB24: Regional
A25: Small | B25: 2-5 Days | C25: 2-5 Days | D25: 3-7 Days | F25: 2-5 Days | G25: 2-5 Days | H25: 2-5 Days | J25: 2-5 Days | K25: 2-5 Days | L25: 2-5 Days | N25: 2-5 Days | O25: 2-5 Days | P25: 3-7 Days | R25: 1-3 Days | S25: 1-3 Days | T25: 2-5 Days | V25: 7-14 Days | W25: 7-14 Days | X25: 7-14 Days | Z25: 7-14 Days | AA25: 7-14 Days | AB25: 7-14 Days
A26: Medium | B26: 2-5 Days | C26: 2-5 Days | D26: 3-7 Days | F26: 2-5 Days | G26: 2-5 Days | H26: 2-5 Days | J26: 2-5 Days | K26: 2-5 Days | L26: 2-5 Days | N26: 2-5 Days | O26: 2-5 Days | P26: 3-7 Days | R26: 1-3 Days | S26: 1-3 Days | T26: 2-5 Days | V26: 7-14 Days | W26: 7-14 Days | X26: 7-14 Days | Z26: 7-14 Days | AA26: 7-14 Days | AB26: 7-14 Days
A27: Large | B27: 3-7 Days | C27: 3-7 Days | D27: 5-10 Days | F27: 3-7 Days | G27: 3-7 Days | H27: 5-10 Days | J27: 3-7 Days | K27: 3-7 Days | L27: 5-10 Days | N27: 3-7 Days | O27: 3-7 Days | P27: 5-10 Days | R27: 1-3 Days | S27: 1-3 Days | T27: 3-7 Days | V27: 7-14 Days | W27: 7-14 Days | X27: 7-14 Days | Z27: 7-14 Days | AA27: 7-14 Days | AB27: 7-14 Days
A28: XL | B28: 5-10 Days | C28: 5-10 Days | D28: 5-10 Days | F28: 5-10 Days | G28: 5-10 Days | H28: 5-10 Days | J28: 5-10 Days | K28: 5-10 Days | L28: 5-10 Days | N28: 5-10 Days | O28: 5-10 Days | P28: 5-10 Days | R28: 1-3 Days | S28: 1-3 Days | T28: 5-10 Days | V28: 7-14 Days | W28: 7-14 Days | X28: 7-14 Days | Z28: 7-14 Days | AA28: 7-14 Days | AB28: 7-14 Days
A29: XXL | B29: 5-10 Days | C29: 5-10 Days | D29: 5-10 Days | F29: 5-10 Days | G29: 5-10 Days | H29: 5-10 Days | J29: 5-10 Days | K29: 5-10 Days | L29: 5-10 Days | N29: 5-10 Days | O29: 5-10 Days | P29: 5-10 Days | R29: 1-3 Days | S29: 1-3 Days | T29: 5-10 Days | V29: 7-14 Days | W29: 7-14 Days | X29: 7-14 Days | Z29: 7-14 Days | AA29: 7-14 Days | AB29: 7-14 Days
A30: Bulky | B30: 5-10 Days | C30: 5-10 Days | D30: 5-10 Days | F30: 5-10 Days | G30: 5-10 Days | H30: 5-10 Days | J30: 5-10 Days | K30: 5-10 Days | L30: 5-10 Days | N30: 5-10 Days | O30: 5-10 Days | P30: 5-10 Days | R30: 1-3 Days | S30: 1-3 Days | T30: 5-10 Days | V30: 7-14 Days | W30: 7-14 Days | X30: 7-14 Days | Z30: 7-14 Days | AA30: 7-14 Days | AB30: 7-14 Days
A32: Priority | B32: From QLD | F32: From VIC | J32: From SA | N32: From NSW | R32: From ACT | V32: From TAS | Z32: From WA
A33: Freight Size | B33: Metro | C33: Metro Outer | D33: Regional | F33: Metro | G33: Metro Outer | H33: Regional | J33: Metro | K33: Metro Outer | L33: Regional | N33: Metro | O33: Metro Outer | P33: Regional | R33: Metro | S33: Metro Outer | T33: Regional | V33: Metro | W33: Metro Outer | X33: Regional | Z33: Metro | AA33: Metro Outer | AB33: Regional
A34: Small | B34: 1-2 Days | C34: 1-2 Days | D34: 2-5 Days | F34: 1-2 Days | G34: 1-2 Days | H34: 2-5 Days | J34: 1-2 Days | K34: 1-2 Days | L34: 2-5 Days | N34: 1-2 Days | O34: 1-2 Days | P34: 2-5 Days | R34: 1-2 Days | S34: 1-2 Days | T34: 1-3 Days | V34: 1-2 Days | W34: 1-2 Days | X34: 2-5 Days | Z34: 1-2 Days | AA34: 1-2 Days | AB34: 2-5 Days
A35: Medium | B35: 1-2 Days | C35: 1-2 Days | D35: 2-5 Days | F35: 1-2 Days | G35: 1-2 Days | H35: 2-5 Days | J35: 1-2 Days | K35: 1-2 Days | L35: 2-5 Days | N35: 1-2 Days | O35: 1-2 Days | P35: 2-5 Days | R35: 1-2 Days | S35: 1-2 Days | T35: 1-3 Days | V35: 1-2 Days | W35: 1-2 Days | X35: 2-5 Days | Z35: 1-2 Days | AA35: 1-2 Days | AB35: 2-5 Days
A36: Large | B36: 2-5 Days | C36: 2-5 Days | D36: 5-10 Days | F36: 2-5 Days | G36: 2-5 Days | H36: 5-10 Days | J36: 2-5 Days | K36: 2-5 Days | L36: 5-10 Days | N36: 2-5 Days | O36: 2-5 Days | P36: 5-10 Days | R36: 1-2 Days | S36: 1-2 Days | T36: 2-7 Days | V36: 7-14 Days | W36: 7-14 Days | X36: 7-14 Days | Z36: 7-14 Days | AA36: 7-14 Days | AB36: 7-14 Days
A37: XL | B37: 3-7 Days | C37: 3-7 Days | D37: 5-10 Days | F37: 3-7 Days | G37: 3-7 Days | H37: 5-10 Days | J37: 3-7 Days | K37: 3-7 Days | L37: 5-10 Days | N37: 3-7 Days | O37: 3-7 Days | P37: 5-10 Days | R37: 1-2 Days | S37: 1-2 Days | T37: 2-7 Days | V37: 7-14 Days | W37: 7-14 Days | X37: 7-14 Days | Z37: 7-14 Days | AA37: 7-14 Days | AB37: 7-14 Days
A38: XXL | B38: 3-7 Days | C38: 3-7 Days | D38: 5-10 Days | F38: 3-7 Days | G38: 3-7 Days | H38: 5-10 Days | J38: 3-7 Days | K38: 3-7 Days | L38: 5-10 Days | N38: 3-7 Days | O38: 3-7 Days | P38: 5-10 Days | R38: 1-2 Days | S38: 1-2 Days | T38: 2-7 Days | V38: 7-14 Days | W38: 7-14 Days | X38: 7-14 Days | Z38: 7-14 Days | AA38: 7-14 Days | AB38: 7-14 Days
A39: Bulky | B39: 3-7 Days | C39: 3-7 Days | D39: 5-10 Days | F39: 3-7 Days | G39: 3-7 Days | H39: 5-10 Days | J39: 3-7 Days | K39: 3-7 Days | L39: 5-10 Days | N39: 3-7 Days | O39: 3-7 Days | P39: 5-10 Days | R39: 1-2 Days | S39: 1-2 Days | T39: 2-7 Days | V39: 7-14 Days | W39: 7-14 Days | X39: 7-14 Days | Z39: 7-14 Days | AA39: 7-14 Days | AB39: 7-14 Days

Sheet NSW
A1: Freight Charges for NSW Orders
A3: Standard | B3: From QLD | F3: From VIC | J3: From SA | N3: From WA | R3: From NSW | V3: From TAS | Z3: From ACT
A4: Freight Size | B4: Metro | C4: Metro Outer | D4: Regional | F4: Metro | G4: Metro Outer | H4: Regional | J4: Metro | K4: Metro Outer | L4: Regional | N4: Metro | O4: Metro Outer | P4: Regional | R4: Metro | S4: Metro Outer | T4: Regional | V4: Metro | W4: Metro Outer | X4: Regional | Z4: Metro | AA4: Metro Outer | AB4: Regional
A5: Small | B5: ='Cost model'!M128 -> 10.5 | C5: ='Cost model'!M129 -> 13.5 | D5: ='Cost model'!M130 -> 18.5 | F5: ='Cost model'!M146 -> 12.5 | G5: ='Cost model'!M147 -> 14.5 | H5: ='Cost model'!M148 -> 21.5 | J5: ='Cost model'!M164 -> 11.5 | K5: ='Cost model'!M165 -> 15.5 | L5: ='Cost model'!M166 -> 18.5 | N5: ='Cost model'!M182 -> 15.5 | O5: ='Cost model'!M183 -> 17.5 | P5: ='Cost model'!M184 -> 22.5 | R5: ='Cost model'!M200 -> 7.5 | S5: ='Cost model'!M201 -> 12.5 | T5: ='Cost model'!M202 -> 17.5 | V5: ='Cost model'!M218 -> 12.5 | W5: ='Cost model'!M219 -> 14.5 | X5: ='Cost model'!M220 -> 25.5 | Z5: ='Cost model'!M236 -> 17.5 | AA5: ='Cost model'!M237 -> 18.5 | AB5: ='Cost model'!M238 -> 22.5
A6: Medium | B6: ='Cost model'!M131 -> 40 | C6: ='Cost model'!M132 -> 50 | D6: ='Cost model'!M133 -> 55 | F6: ='Cost model'!M149 -> 45 | G6: ='Cost model'!M150 -> 55 | H6: ='Cost model'!M151 -> 55 | J6: ='Cost model'!M167 -> 60 | K6: ='Cost model'!M168 -> 60 | L6: ='Cost model'!M169 -> 60 | N6: ='Cost model'!M185 -> 55 | O6: ='Cost model'!M186 -> 55 | P6: ='Cost model'!M187 -> 75 | R6: ='Cost model'!M203 -> 26.5 | S6: ='Cost model'!M204 -> 45 | T6: ='Cost model'!M205 -> 50 | V6: ='Cost model'!M221 -> 50 | W6: ='Cost model'!M222 -> 60 | X6: ='Cost model'!M223 -> 70 | Z6: ='Cost model'!M239 -> 55 | AA6: ='Cost model'!M240 -> 55 | AB6: ='Cost model'!M241 -> 75
A7: Large | B7: ='Cost model'!M134 -> 80 | C7: ='Cost model'!M135 -> 80 | D7: ='Cost model'!M136 -> 105 | F7: ='Cost model'!M152 -> 65 | G7: ='Cost model'!M153 -> 100 | H7: ='Cost model'!M154 -> 130 | J7: ='Cost model'!M170 -> 80 | K7: ='Cost model'!M171 -> 90 | L7: ='Cost model'!M172 -> 115 | N7: ='Cost model'!M188 -> 95 | O7: ='Cost model'!M189 -> 105 | P7: ='Cost model'!M190 -> 140 | R7: ='Cost model'!M206 -> 55 | S7: ='Cost model'!M207 -> 75 | T7: ='Cost model'!M208 -> 80 | V7: ='Cost model'!M224 -> 85 | W7: ='Cost model'!M225 -> 95 | X7: ='Cost model'!M226 -> 125 | Z7: ='Cost model'!M242 -> 95 | AA7: ='Cost model'!M243 -> 110 | AB7: ='Cost model'!M244 -> 145
A8: XL | B8: ='Cost model'!M137 -> 120 | C8: ='Cost model'!M138 -> 150 | D8: ='Cost model'!M139 -> 170 | F8: ='Cost model'!M155 -> 125 | G8: ='Cost model'!M156 -> 145 | H8: ='Cost model'!M157 -> 195 | J8: ='Cost model'!M173 -> 125 | K8: ='Cost model'!M174 -> 170 | L8: ='Cost model'!M175 -> 195 | N8: ='Cost model'!M191 -> 160 | O8: ='Cost model'!M192 -> 190 | P8: ='Cost model'!M193 -> 230 | R8: ='Cost model'!M209 -> 105 | S8: ='Cost model'!M210 -> 135 | T8: ='Cost model'!M211 -> 175 | V8: ='Cost model'!M227 -> 145 | W8: ='Cost model'!M228 -> 170 | X8: ='Cost model'!M229 -> 205 | Z8: ='Cost model'!M245 -> 165 | AA8: ='Cost model'!M246 -> 195 | AB8: ='Cost model'!M247 -> 235
A9: XXL | B9: ='Cost model'!M140 -> 155 | C9: ='Cost model'!M141 -> 230 | D9: ='Cost model'!M142 -> 270 | F9: ='Cost model'!M158 -> 175 | G9: ='Cost model'!M159 -> 255 | H9: ='Cost model'!M160 -> 300 | J9: ='Cost model'!M176 -> 170 | K9: ='Cost model'!M177 -> 255 | L9: ='Cost model'!M178 -> 310 | N9: ='Cost model'!M194 -> 200 | O9: ='Cost model'!M195 -> 300 | P9: ='Cost model'!M196 -> 360 | R9: ='Cost model'!M212 -> 120 | S9: ='Cost model'!M213 -> 155 | T9: ='Cost model'!M214 -> 240 | V9: ='Cost model'!M230 -> 180 | W9: ='Cost model'!M231 -> 270 | X9: ='Cost model'!M232 -> 325 | Z9: ='Cost model'!M248 -> 210 | AA9: ='Cost model'!M249 -> 310 | AB9: ='Cost model'!M250 -> 375
A10: Bulky | B10: ='Cost model'!M143 -> 235 | C10: ='Cost model'!M144 -> 330 | D10: ='Cost model'!M145 -> 385 | F10: ='Cost model'!M161 -> 230 | G10: ='Cost model'!M162 -> 355 | H10: ='Cost model'!M163 -> 420 | J10: ='Cost model'!M179 -> 240 | K10: ='Cost model'!M180 -> 385 | L10: ='Cost model'!M181 -> 460 | N10: ='Cost model'!M197 -> 280 | O10: ='Cost model'!M198 -> 465 | P10: ='Cost model'!M199 -> 505 | R10: ='Cost model'!M215 -> 135 | S10: ='Cost model'!M216 -> 215 | T10: ='Cost model'!M217 -> 285 | V10: ='Cost model'!M233 -> 250 | W10: ='Cost model'!M234 -> 390 | X10: ='Cost model'!M235 -> 460 | Z10: ='Cost model'!M251 -> 275 | AA10: ='Cost model'!M252 -> 445 | AB10: ='Cost model'!M253 -> 525
A12: Priority | B12: From QLD | F12: From VIC | J12: From SA | N12: From WA | R12: From NSW | V12: From TAS | Z12: From ACT
A13: Freight Size | B13: Metro | C13: Metro Outer | D13: Regional | F13: Metro | G13: Metro Outer | H13: Regional | J13: Metro | K13: Metro Outer | L13: Regional | N13: Metro | O13: Metro Outer | P13: Regional | R13: Metro | S13: Metro Outer | T13: Regional | V13: Metro | W13: Metro Outer | X13: Regional | Z13: Metro | AA13: Metro Outer | AB13: Regional
A14: Small | B14: ='Cost model'!N128 -> 15.5 | C14: ='Cost model'!N129 -> 18.5 | D14: ='Cost model'!N130 -> 25.5 | F14: ='Cost model'!N146 -> 17.5 | G14: ='Cost model'!N147 -> 19.5 | H14: ='Cost model'!N148 -> 29.5 | J14: ='Cost model'!N164 -> 16.5 | K14: ='Cost model'!N165 -> 21.5 | L14: ='Cost model'!N166 -> 25.5 | N14: ='Cost model'!N182 -> 21.5 | O14: ='Cost model'!N183 -> 23.5 | P14: ='Cost model'!N184 -> 35 | R14: ='Cost model'!N200 -> 12.5 | S14: ='Cost model'!N201 -> 17.5 | T14: ='Cost model'!N202 -> 23.5 | V14: ='Cost model'!N218 -> 17.5 | W14: ='Cost model'!N219 -> 19.5 | X14: ='Cost model'!N220 -> 35 | Z14: ='Cost model'!N236 -> 23.5 | AA14: ='Cost model'!N237 -> 25.5 | AB14: ='Cost model'!N238 -> 35
A15: Medium | B15: ='Cost model'!N131 -> 55 | C15: ='Cost model'!N132 -> 65 | D15: ='Cost model'!N133 -> 70 | F15: ='Cost model'!N149 -> 60 | G15: ='Cost model'!N150 -> 70 | H15: ='Cost model'!N151 -> 70 | J15: ='Cost model'!N167 -> 80 | K15: ='Cost model'!N168 -> 80 | L15: ='Cost model'!N169 -> 80 | N15: ='Cost model'!N185 -> 70 | O15: ='Cost model'!N186 -> 70 | P15: ='Cost model'!N187 -> 95 | R15: ='Cost model'!N203 -> 35 | S15: ='Cost model'!N204 -> 60 | T15: ='Cost model'!N205 -> 65 | V15: ='Cost model'!N221 -> 65 | W15: ='Cost model'!N222 -> 80 | X15: ='Cost model'!N223 -> 90 | Z15: ='Cost model'!N239 -> 70 | AA15: ='Cost model'!N240 -> 70 | AB15: ='Cost model'!N241 -> 95
A16: Large | B16: ='Cost model'!N134 -> 110 | C16: ='Cost model'!N135 -> 110 | D16: ='Cost model'!N136 -> 145 | F16: ='Cost model'!N152 -> 90 | G16: ='Cost model'!N153 -> 135 | H16: ='Cost model'!N154 -> 180 | J16: ='Cost model'!N170 -> 110 | K16: ='Cost model'!N171 -> 125 | L16: ='Cost model'!N172 -> 160 | N16: ='Cost model'!N188 -> 130 | O16: ='Cost model'!N189 -> 145 | P16: ='Cost model'!N190 -> 190 | R16: ='Cost model'!N206 -> 75 | S16: ='Cost model'!N207 -> 105 | T16: ='Cost model'!N208 -> 110 | V16: ='Cost model'!N224 -> 115 | W16: ='Cost model'!N225 -> 130 | X16: ='Cost model'!N226 -> 170 | Z16: ='Cost model'!N242 -> 130 | AA16: ='Cost model'!N243 -> 150 | AB16: ='Cost model'!N244 -> 200
A17: XL | B17: ='Cost model'!N137 -> 145 | C17: ='Cost model'!N138 -> 180 | D17: ='Cost model'!N139 -> 205 | F17: ='Cost model'!N155 -> 150 | G17: ='Cost model'!N156 -> 175 | H17: ='Cost model'!N157 -> 235 | J17: ='Cost model'!N173 -> 150 | K17: ='Cost model'!N174 -> 205 | L17: ='Cost model'!N175 -> 235 | N17: ='Cost model'!N191 -> 195 | O17: ='Cost model'!N192 -> 230 | P17: ='Cost model'!N193 -> 280 | R17: ='Cost model'!N209 -> 130 | S17: ='Cost model'!N210 -> 165 | T17: ='Cost model'!N211 -> 210 | V17: ='Cost model'!N227 -> 175 | W17: ='Cost model'!N228 -> 205 | X17: ='Cost model'!N229 -> 250 | Z17: ='Cost model'!N245 -> 200 | AA17: ='Cost model'!N246 -> 235 | AB17: ='Cost model'!N247 -> 285
A18: XXL | B18: ='Cost model'!N140 -> 190 | C18: ='Cost model'!N141 -> 230 | D18: ='Cost model'!N142 -> 270 | F18: ='Cost model'!N158 -> 210 | G18: ='Cost model'!N159 -> 255 | H18: ='Cost model'!N160 -> 300 | J18: ='Cost model'!N176 -> 205 | K18: ='Cost model'!N177 -> 255 | L18: ='Cost model'!N178 -> 310 | N18: ='Cost model'!N194 -> 240 | O18: ='Cost model'!N195 -> 300 | P18: ='Cost model'!N196 -> 360 | R18: ='Cost model'!N212 -> 145 | S18: ='Cost model'!N213 -> 190 | T18: ='Cost model'!N214 -> 290 | V18: ='Cost model'!N230 -> 220 | W18: ='Cost model'!N231 -> 270 | X18: ='Cost model'!N232 -> 325 | Z18: ='Cost model'!N248 -> 255 | AA18: ='Cost model'!N249 -> 310 | AB18: ='Cost model'!N250 -> 375
A19: Bulky | B19: ='Cost model'!N143 -> 285 | C19: ='Cost model'!N144 -> 330 | D19: ='Cost model'!N145 -> 385 | F19: ='Cost model'!N161 -> 280 | G19: ='Cost model'!N162 -> 355 | H19: ='Cost model'!N163 -> 420 | J19: ='Cost model'!N179 -> 290 | K19: ='Cost model'!N180 -> 385 | L19: ='Cost model'!N181 -> 460 | N19: ='Cost model'!N197 -> 340 | O19: ='Cost model'!N198 -> 465 | P19: ='Cost model'!N199 -> 505 | R19: ='Cost model'!N215 -> 165 | S19: ='Cost model'!N216 -> 260 | T19: ='Cost model'!N217 -> 345 | V19: ='Cost model'!N233 -> 300 | W19: ='Cost model'!N234 -> 390 | X19: ='Cost model'!N235 -> 460 | Z19: ='Cost model'!N251 -> 330 | AA19: ='Cost model'!N252 -> 445 | AB19: ='Cost model'!N253 -> 525
A21: Delivery time frames for NSW Orders
A23: Standard | B23: From QLD | F23: From VIC | J23: From SA | N23: From WA | R23: From NSW | V23: From TAS | Z23: From ACT
A24: Freight Size | B24: Metro | C24: Metro Outer | D24: Regional | F24: Metro | G24: Metro Outer | H24: Regional | J24: Metro | K24: Metro Outer | L24: Regional | N24: Metro | O24: Metro Outer | P24: Regional | R24: Metro | S24: Metro Outer | T24: Regional | V24: Metro | W24: Metro Outer | X24: Regional | Z24: Metro | AA24: Metro Outer | AB24: Regional
A25: Small | B25: 1-2 Days | C25: 1-3 Days | D25: 2-5 Days | F25: 1-2 Days | G25: 1-3 Days | H25: 2-5 Days | J25: 2-5 Days | K25: 2-5 Days | L25: 2-5 Days | N25: 7-10 Days | O25: 7-10 Days | P25: 7-10 Days | R25: 1-2 Days | S25: 1-3 Days | T25: 2-5 Days | V25: 7-14 Days | W25: 7-14 Days | X25: 7-14 Days | Z25: 7-14 Days | AA25: 7-14 Days | AB25: 7-14 Days
A26: Medium | B26: 1-2 Days | C26: 1-3 Days | D26: 2-5 Days | F26: 1-2 Days | G26: 1-3 Days | H26: 2-5 Days | J26: 2-5 Days | K26: 2-5 Days | L26: 2-5 Days | N26: 7-10 Days | O26: 7-10 Days | P26: 7-10 Days | R26: 1-2 Days | S26: 1-3 Days | T26: 2-5 Days | V26: 7-14 Days | W26: 7-14 Days | X26: 7-14 Days | Z26: 7-14 Days | AA26: 7-14 Days | AB26: 7-14 Days
A27: Large | B27: 1-2 Days | C27: 1-3 Days | D27: 3-7 Days | F27: 1-2 Days | G27: 1-3 Days | H27: 3-7 Days | J27: 3-7 Days | K27: 3-7 Days | L27: 5-10 Days | N27: 7-10 Days | O27: 7-10 Days | P27: 7-10 Days | R27: 1-2 Days | S27: 1-3 Days | T27: 3-7 Days | V27: 7-14 Days | W27: 7-14 Days | X27: 7-14 Days | Z27: 7-14 Days | AA27: 7-14 Days | AB27: 7-14 Days
A28: XL | B28: 2-5 Days | C28: 2-5 Days | D28: 5-10 Days | F28: 2-5 Days | G28: 2-5 Days | H28: 5-10 Days | J28: 5-10 Days | K28: 5-10 Days | L28: 5-10 Days | N28: 7-10 Days | O28: 7-10 Days | P28: 7-10 Days | R28: 2-5 Days | S28: 2-5 Days | T28: 5-10 Days | V28: 7-14 Days | W28: 7-14 Days | X28: 7-14 Days | Z28: 7-14 Days | AA28: 7-14 Days | AB28: 7-14 Days
A29: XXL | B29: 2-5 Days | C29: 2-5 Days | D29: 5-10 Days | F29: 2-5 Days | G29: 2-5 Days | H29: 5-10 Days | J29: 5-10 Days | K29: 5-10 Days | L29: 5-10 Days | N29: 7-10 Days | O29: 7-10 Days | P29: 7-10 Days | R29: 2-5 Days | S29: 2-5 Days | T29: 5-10 Days | V29: 7-14 Days | W29: 7-14 Days | X29: 7-14 Days | Z29: 7-14 Days | AA29: 7-14 Days | AB29: 7-14 Days
A30: Bulky | B30: 2-5 Days | C30: 2-5 Days | D30: 5-10 Days | F30: 2-5 Days | G30: 2-5 Days | H30: 5-10 Days | J30: 5-10 Days | K30: 5-10 Days | L30: 5-10 Days | N30: 7-10 Days | O30: 7-10 Days | P30: 7-10 Days | R30: 2-5 Days | S30: 2-5 Days | T30: 5-10 Days | V30: 7-14 Days | W30: 7-14 Days | X30: 7-14 Days | Z30: 7-14 Days | AA30: 7-14 Days | AB30: 7-14 Days
A32: Priority | B32: From QLD | F32: From VIC | J32: From SA | N32: From WA | R32: From NSW | V32: From TAS | Z32: From ACT
A33: Freight Size | B33: Metro | C33: Metro Outer | D33: Regional | F33: Metro | G33: Metro Outer | H33: Regional | J33: Metro | K33: Metro Outer | L33: Regional | N33: Metro | O33: Metro Outer | P33: Regional | R33: Metro | S33: Metro Outer | T33: Regional | V33: Metro | W33: Metro Outer | X33: Regional | Z33: Metro | AA33: Metro Outer | AB33: Regional
A34: Small | B34: 1-2 Days | C34: 1-2 Days | D34: 1-3 Days | F34: 1-2 Days | G34: 1-2 Days | H34: 1-3 Days | J34: 1-2 Days | K34: 1-2 Days | L34: 2-5 Days | N34: 1-2 Days | O34: 1-2 Days | P34: 2-5 Days | R34: 1-2 Days | S34: 1-2 Days | T34: 1-3 Days | V34: 1-2 Days | W34: 1-2 Days | X34: 2-5 Days | Z34: 1-2 Days | AA34: 1-2 Days | AB34: 2-5 Days
A35: Medium | B35: 1-2 Days | C35: 1-2 Days | D35: 1-3 Days | F35: 1-2 Days | G35: 1-2 Days | H35: 1-3 Days | J35: 1-2 Days | K35: 1-2 Days | L35: 2-5 Days | N35: 1-2 Days | O35: 1-2 Days | P35: 2-5 Days | R35: 1-2 Days | S35: 1-2 Days | T35: 1-3 Days | V35: 1-2 Days | W35: 1-2 Days | X35: 2-5 Days | Z35: 1-2 Days | AA35: 1-2 Days | AB35: 2-5 Days
A36: Large | B36: 1-2 Days | C36: 1-2 Days | D36: 2-7 Days | F36: 1-2 Days | G36: 1-2 Days | H36: 2-7 Days | J36: 2-5 Days | K36: 2-5 Days | L36: 5-10 Days | N36: 7-10 Days | O36: 7-10 Days | P36: 7-14 Days | R36: 1-2 Days | S36: 1-2 Days | T36: 2-7 Days | V36: 7-14 Days | W36: 7-14 Days | X36: 7-14 Days | Z36: 7-14 Days | AA36: 7-14 Days | AB36: 7-14 Days
A37: XL | B37: 1-3 Days | C37: 1-3 Days | D37: 2-7 Days | F37: 1-3 Days | G37: 1-3 Days | H37: 2-7 Days | J37: 3-7 Days | K37: 3-7 Days | L37: 5-10 Days | N37: 7-10 Days | O37: 7-10 Days | P37: 7-14 Days | R37: 1-3 Days | S37: 1-3 Days | T37: 2-7 Days | V37: 7-14 Days | W37: 7-14 Days | X37: 7-14 Days | Z37: 7-14 Days | AA37: 7-14 Days | AB37: 7-14 Days
A38: XXL | B38: 1-3 Days | C38: 1-3 Days | D38: 2-7 Days | F38: 1-3 Days | G38: 1-3 Days | H38: 2-7 Days | J38: 3-7 Days | K38: 3-7 Days | L38: 5-10 Days | N38: 7-10 Days | O38: 7-10 Days | P38: 7-14 Days | R38: 1-3 Days | S38: 1-3 Days | T38: 2-7 Days | V38: 7-14 Days | W38: 7-14 Days | X38: 7-14 Days | Z38: 7-14 Days | AA38: 7-14 Days | AB38: 7-14 Days
A39: Bulky | B39: 1-3 Days | C39: 1-3 Days | D39: 2-7 Days | F39: 1-3 Days | G39: 1-3 Days | H39: 2-7 Days | J39: 3-7 Days | K39: 3-7 Days | L39: 5-10 Days | N39: 7-10 Days | O39: 7-10 Days | P39: 7-14 Days | R39: 1-3 Days | S39: 1-3 Days | T39: 2-7 Days | V39: 7-14 Days | W39: 7-14 Days | X39: 7-14 Days | Z39: 7-14 Days | AA39: 7-14 Days | AB39: 7-14 Days

Sheet NT
A1: Freight Charges for NT Orders
A3: Standard | B3: From SA | F3: From VIC | J3: From WA | N3: From QLD | R3: From NSW | V3: From TAS | Z3: From ACT
A4: Freight Size | B4: Metro | C4: Metro Outer | D4: Regional | F4: Metro | G4: Metro Outer | H4: Regional | J4: Metro | K4: Metro Outer | L4: Regional | N4: Metro | O4: Metro Outer | P4: Regional | R4: Metro | S4: Metro Outer | T4: Regional | V4: Metro | W4: Metro Outer | X4: Regional | Z4: Metro | AA4: Metro Outer | AB4: Regional
A5: Small | B5: ='Cost model'!M254 -> 20.5 | C5: ='Cost model'!M255 -> 20.5 | D5: ='Cost model'!M256 -> 25.5 | F5: ='Cost model'!M272 -> 22.5 | G5: ='Cost model'!M273 -> 22.5 | H5: ='Cost model'!M274 -> 26.5 | J5: ='Cost model'!M290 -> 22.5 | K5: ='Cost model'!M291 -> 22.5 | L5: ='Cost model'!M292 -> 24.5 | N5: ='Cost model'!M308 -> 15.5 | O5: ='Cost model'!M309 -> 17.5 | P5: ='Cost model'!M310 -> 21.5 | R5: ='Cost model'!M326 -> 15.5 | S5: ='Cost model'!M327 -> 17.5 | T5: ='Cost model'!M328 -> 23.5 | V5: ='Cost model'!M344 -> 15.5 | W5: ='Cost model'!M345 -> 17.5 | X5: ='Cost model'!M346 -> 23.5 | Z5: ='Cost model'!M362 -> 21.5 | AA5: ='Cost model'!M363 -> 21.5 | AB5: ='Cost model'!M364 -> 27.5
A6: Medium | B6: ='Cost model'!M257 -> 60 | C6: ='Cost model'!M258 -> 70 | D6: ='Cost model'!M259 -> 75 | F6: ='Cost model'!M275 -> 70 | G6: ='Cost model'!M276 -> 70 | H6: ='Cost model'!M277 -> 80 | J6: ='Cost model'!M293 -> 75 | K6: ='Cost model'!M294 -> 75 | L6: ='Cost model'!M295 -> 75 | N6: ='Cost model'!M311 -> 55 | O6: ='Cost model'!M312 -> 60 | P6: ='Cost model'!M313 -> 70 | R6: ='Cost model'!M329 -> 55 | S6: ='Cost model'!M330 -> 60 | T6: ='Cost model'!M331 -> 70 | V6: ='Cost model'!M347 -> 55 | W6: ='Cost model'!M348 -> 60 | X6: ='Cost model'!M349 -> 70 | Z6: ='Cost model'!M365 -> 70 | AA6: ='Cost model'!M366 -> 75 | AB6: ='Cost model'!M367 -> 85
A7: Large | B7: ='Cost model'!M260 -> 115 | C7: ='Cost model'!M261 -> 120 | D7: ='Cost model'!M262 -> 155 | F7: ='Cost model'!M278 -> 110 | G7: ='Cost model'!M279 -> 125 | H7: ='Cost model'!M280 -> 165 | J7: ='Cost model'!M296 -> 105 | K7: ='Cost model'!M297 -> 115 | L7: ='Cost model'!M298 -> 155 | N7: ='Cost model'!M314 -> 95 | O7: ='Cost model'!M315 -> 105 | P7: ='Cost model'!M316 -> 140 | R7: ='Cost model'!M332 -> 95 | S7: ='Cost model'!M333 -> 110 | T7: ='Cost model'!M334 -> 145 | V7: ='Cost model'!M350 -> 95 | W7: ='Cost model'!M351 -> 110 | X7: ='Cost model'!M352 -> 145 | Z7: ='Cost model'!M368 -> 115 | AA7: ='Cost model'!M369 -> 130 | AB7: ='Cost model'!M370 -> 175
A8: XL | B8: ='Cost model'!M263 -> 185 | C8: ='Cost model'!M264 -> 220 | D8: ='Cost model'!M265 -> 265 | F8: ='Cost model'!M281 -> 185 | G8: ='Cost model'!M282 -> 225 | H8: ='Cost model'!M283 -> 270 | J8: ='Cost model'!M299 -> 180 | K8: ='Cost model'!M300 -> 210 | L8: ='Cost model'!M301 -> 245 | N8: ='Cost model'!M317 -> 160 | O8: ='Cost model'!M318 -> 190 | P8: ='Cost model'!M319 -> 230 | R8: ='Cost model'!M335 -> 170 | S8: ='Cost model'!M336 -> 195 | T8: ='Cost model'!M337 -> 235 | V8: ='Cost model'!M353 -> 165 | W8: ='Cost model'!M354 -> 195 | X8: ='Cost model'!M355 -> 235 | Z8: ='Cost model'!M371 -> 200 | AA8: ='Cost model'!M372 -> 235 | AB8: ='Cost model'!M373 -> 285
A9: XXL | B9: ='Cost model'!M266 -> 235 | C9: ='Cost model'!M267 -> 350 | D9: ='Cost model'!M268 -> 415 | F9: ='Cost model'!M284 -> 235 | G9: ='Cost model'!M285 -> 350 | H9: ='Cost model'!M286 -> 420 | J9: ='Cost model'!M302 -> 225 | K9: ='Cost model'!M303 -> 330 | L9: ='Cost model'!M304 -> 400 | N9: ='Cost model'!M320 -> 200 | O9: ='Cost model'!M321 -> 300 | P9: ='Cost model'!M322 -> 355 | R9: ='Cost model'!M338 -> 210 | S9: ='Cost model'!M339 -> 310 | T9: ='Cost model'!M340 -> 375 | V9: ='Cost model'!M356 -> 210 | W9: ='Cost model'!M357 -> 310 | X9: ='Cost model'!M358 -> 370 | Z9: ='Cost model'!M374 -> 250 | AA9: ='Cost model'!M375 -> 375 | AB9: ='Cost model'!M376 -> 445
A10: Bulky | B10: ='Cost model'!M269 -> 325 | C10: ='Cost model'!M270 -> 500 | D10: ='Cost model'!M271 -> 590 | F10: ='Cost model'!M287 -> 330 | G10: ='Cost model'!M288 -> 505 | H10: ='Cost model'!M289 -> 595 | J10: ='Cost model'!M305 -> 310 | K10: ='Cost model'!M306 -> 480 | L10: ='Cost model'!M307 -> 560 | N10: ='Cost model'!M323 -> 280 | O10: ='Cost model'!M324 -> 430 | P10: ='Cost model'!M325 -> 505 | R10: ='Cost model'!M341 -> 290 | S10: ='Cost model'!M342 -> 445 | T10: ='Cost model'!M343 -> 525 | V10: ='Cost model'!M359 -> 290 | W10: ='Cost model'!M360 -> 445 | X10: ='Cost model'!M361 -> 525 | Z10: ='Cost model'!M377 -> 345 | AA10: ='Cost model'!M378 -> 535 | AB10: ='Cost model'!M379 -> 625
A12: Priority | B12: From SA | F12: From VIC | J12: From WA | N12: From QLD | R12: From NSW | V12: From TAS | Z12: From ACT
A13: Freight Size | B13: Metro | C13: Metro Outer | D13: Regional | F13: Metro | G13: Metro Outer | H13: Regional | J13: Metro | K13: Metro Outer | L13: Regional | N13: Metro | O13: Metro Outer | P13: Regional | R13: Metro | S13: Metro Outer | T13: Regional | V13: Metro | W13: Metro Outer | X13: Regional | Z13: Metro | AA13: Metro Outer | AB13: Regional
A14: Small | B14: ='Cost model'!N254 -> 27.5 | C14: ='Cost model'!N255 -> 27.5 | D14: ='Cost model'!N256 -> 35 | F14: ='Cost model'!N272 -> 35 | G14: ='Cost model'!N273 -> 35 | H14: ='Cost model'!N274 -> 40 | J14: ='Cost model'!N290 -> 35 | K14: ='Cost model'!N291 -> 35 | L14: ='Cost model'!N292 -> 35 | N14: ='Cost model'!N308 -> 21.5 | O14: ='Cost model'!N309 -> 23.5 | P14: ='Cost model'!N310 -> 29.5 | R14: ='Cost model'!N326 -> 21.5 | S14: ='Cost model'!N327 -> 23.5 | T14: ='Cost model'!N328 -> 35 | V14: ='Cost model'!N344 -> 21.5 | W14: ='Cost model'!N345 -> 23.5 | X14: ='Cost model'!N346 -> 35 | Z14: ='Cost model'!N362 -> 29.5 | AA14: ='Cost model'!N363 -> 29.5 | AB14: ='Cost model'!N364 -> 40
A15: Medium | B15: ='Cost model'!N257 -> 80 | C15: ='Cost model'!N258 -> 90 | D15: ='Cost model'!N259 -> 95 | F15: ='Cost model'!N275 -> 90 | G15: ='Cost model'!N276 -> 90 | H15: ='Cost model'!N277 -> 105 | J15: ='Cost model'!N293 -> 95 | K15: ='Cost model'!N294 -> 95 | L15: ='Cost model'!N295 -> 95 | N15: ='Cost model'!N311 -> 70 | O15: ='Cost model'!N312 -> 80 | P15: ='Cost model'!N313 -> 90 | R15: ='Cost model'!N329 -> 70 | S15: ='Cost model'!N330 -> 80 | T15: ='Cost model'!N331 -> 90 | V15: ='Cost model'!N347 -> 70 | W15: ='Cost model'!N348 -> 80 | X15: ='Cost model'!N349 -> 90 | Z15: ='Cost model'!N365 -> 90 | AA15: ='Cost model'!N366 -> 95 | AB15: ='Cost model'!N367 -> 110
A16: Large | B16: ='Cost model'!N260 -> 160 | C16: ='Cost model'!N261 -> 165 | D16: ='Cost model'!N262 -> 210 | F16: ='Cost model'!N278 -> 150 | G16: ='Cost model'!N279 -> 170 | H16: ='Cost model'!N280 -> 225 | J16: ='Cost model'!N296 -> 145 | K16: ='Cost model'!N297 -> 160 | L16: ='Cost model'!N298 -> 210 | N16: ='Cost model'!N314 -> 130 | O16: ='Cost model'!N315 -> 145 | P16: ='Cost model'!N316 -> 190 | R16: ='Cost model'!N332 -> 130 | S16: ='Cost model'!N333 -> 150 | T16: ='Cost model'!N334 -> 200 | V16: ='Cost model'!N350 -> 130 | W16: ='Cost model'!N351 -> 150 | X16: ='Cost model'!N352 -> 200 | Z16: ='Cost model'!N368 -> 160 | AA16: ='Cost model'!N369 -> 180 | AB16: ='Cost model'!N370 -> 240
A17: XL | B17: ='Cost model'!N263 -> 225 | C17: ='Cost model'!N264 -> 265 | D17: ='Cost model'!N265 -> 320 | F17: ='Cost model'!N281 -> 225 | G17: ='Cost model'!N282 -> 270 | H17: ='Cost model'!N283 -> 325 | J17: ='Cost model'!N299 -> 220 | K17: ='Cost model'!N300 -> 255 | L17: ='Cost model'!N301 -> 295 | N17: ='Cost model'!N317 -> 195 | O17: ='Cost model'!N318 -> 230 | P17: ='Cost model'!N319 -> 280 | R17: ='Cost model'!N335 -> 205 | S17: ='Cost model'!N336 -> 235 | T17: ='Cost model'!N337 -> 285 | V17: ='Cost model'!N353 -> 200 | W17: ='Cost model'!N354 -> 235 | X17: ='Cost model'!N355 -> 285 | Z17: ='Cost model'!N371 -> 240 | AA17: ='Cost model'!N372 -> 285 | AB17: ='Cost model'!N373 -> 345
A18: XXL | B18: ='Cost model'!N266 -> 285 | C18: ='Cost model'!N267 -> 350 | D18: ='Cost model'!N268 -> 415 | F18: ='Cost model'!N284 -> 285 | G18: ='Cost model'!N285 -> 350 | H18: ='Cost model'!N286 -> 420 | J18: ='Cost model'!N302 -> 270 | K18: ='Cost model'!N303 -> 330 | L18: ='Cost model'!N304 -> 400 | N18: ='Cost model'!N320 -> 240 | O18: ='Cost model'!N321 -> 300 | P18: ='Cost model'!N322 -> 355 | R18: ='Cost model'!N338 -> 255 | S18: ='Cost model'!N339 -> 310 | T18: ='Cost model'!N340 -> 375 | V18: ='Cost model'!N356 -> 255 | W18: ='Cost model'!N357 -> 310 | X18: ='Cost model'!N358 -> 370 | Z18: ='Cost model'!N374 -> 300 | AA18: ='Cost model'!N375 -> 375 | AB18: ='Cost model'!N376 -> 445
A19: Bulky | B19: ='Cost model'!N269 -> 390 | C19: ='Cost model'!N270 -> 500 | D19: ='Cost model'!N271 -> 590 | F19: ='Cost model'!N287 -> 400 | G19: ='Cost model'!N288 -> 505 | H19: ='Cost model'!N289 -> 595 | J19: ='Cost model'!N305 -> 375 | K19: ='Cost model'!N306 -> 480 | L19: ='Cost model'!N307 -> 560 | N19: ='Cost model'!N323 -> 340 | O19: ='Cost model'!N324 -> 430 | P19: ='Cost model'!N325 -> 505 | R19: ='Cost model'!N341 -> 350 | S19: ='Cost model'!N342 -> 445 | T19: ='Cost model'!N343 -> 525 | V19: ='Cost model'!N359 -> 350 | W19: ='Cost model'!N360 -> 445 | X19: ='Cost model'!N361 -> 525 | Z19: ='Cost model'!N377 -> 415 | AA19: ='Cost model'!N378 -> 535 | AB19: ='Cost model'!N379 -> 625
A21: Delivery time frames for NT Orders
A23: Standard | B23: From SA | F23: From VIC | J23: From WA | N23: From QLD | R23: From NSW | V23: From TAS | Z23: From ACT
A24: Freight Size | B24: Metro | C24: Metro Outer | D24: Regional | F24: Metro | G24: Metro Outer | H24: Regional | J24: Metro | K24: Metro Outer | L24: Regional | N24: Metro | O24: Metro Outer | P24: Regional | R24: Metro | S24: Metro Outer | T24: Regional | V24: Metro | W24: Metro Outer | X24: Regional | Z24: Metro | AA24: Metro Outer | AB24: Regional
A25: Small | B25: 1-2 Days | C25: 1-3 Days | D25: 2-5 Days | F25: 2-5 Days | G25: 3-7 Days | H25: 5-10 Days | J25: 2-5 Days | K25: 2-5 Days | L25: 3-7 Days | N25: 2-5 Days | O25: 2-5 Days | P25: 3-7 Days | R25: 2-5 Days | S25: 2-5 Days | T25: 3-7 Days | V25: 7-14 Days | W25: 7-14 Days | X25: 7-14 Days | Z25: 7-14 Days | AA25: 7-14 Days | AB25: 7-14 Days
A26: Medium | B26: 1-2 Days | C26: 1-3 Days | D26: 2-5 Days | F26: 2-5 Days | G26: 3-7 Days | H26: 5-10 Days | J26: 2-5 Days | K26: 2-5 Days | L26: 3-7 Days | N26: 2-5 Days | O26: 2-5 Days | P26: 3-7 Days | R26: 2-5 Days | S26: 2-5 Days | T26: 3-7 Days | V26: 7-14 Days | W26: 7-14 Days | X26: 7-14 Days | Z26: 7-14 Days | AA26: 7-14 Days | AB26: 7-14 Days
A27: Large | B27: 1-2 Days | C27: 1-3 Days | D27: 3-7 Days | F27: 3-7 Days | G27: 3-7 Days | H27: 5-10 Days | J27: 5-10 Days | K27: 5-10 Days | L27: 5-10 Days | N27: 5-10 Days | O27: 5-10 Days | P27: 5-10 Days | R27: 5-10 Days | S27: 5-10 Days | T27: 5-10 Days | V27: 7-14 Days | W27: 7-14 Days | X27: 7-14 Days | Z27: 7-14 Days | AA27: 7-14 Days | AB27: 7-14 Days
A28: XL | B28: 1-2 Days | C28: 1-3 Days | D28: 5-10 Days | F28: 5-10 Days | G28: 5-10 Days | H28: 5-10 Days | J28: 5-10 Days | K28: 5-10 Days | L28: 5-10 Days | N28: 5-10 Days | O28: 5-10 Days | P28: 5-10 Days | R28: 5-10 Days | S28: 5-10 Days | T28: 5-10 Days | V28: 7-14 Days | W28: 7-14 Days | X28: 7-14 Days | Z28: 7-14 Days | AA28: 7-14 Days | AB28: 7-14 Days
A29: XXL | B29: 1-2 Days | C29: 1-3 Days | D29: 5-10 Days | F29: 5-10 Days | G29: 5-10 Days | H29: 5-10 Days | J29: 5-10 Days | K29: 5-10 Days | L29: 5-10 Days | N29: 5-10 Days | O29: 5-10 Days | P29: 5-10 Days | R29: 5-10 Days | S29: 5-10 Days | T29: 5-10 Days | V29: 7-14 Days | W29: 7-14 Days | X29: 7-14 Days | Z29: 7-14 Days | AA29: 7-14 Days | AB29: 7-14 Days
A30: Bulky | B30: 1-2 Days | C30: 1-3 Days | D30: 5-10 Days | F30: 5-10 Days | G30: 5-10 Days | H30: 5-10 Days | J30: 5-10 Days | K30: 5-10 Days | L30: 5-10 Days | N30: 5-10 Days | O30: 5-10 Days | P30: 5-10 Days | R30: 5-10 Days | S30: 5-10 Days | T30: 5-10 Days | V30: 7-14 Days | W30: 7-14 Days | X30: 7-14 Days | Z30: 7-14 Days | AA30: 7-14 Days | AB30: 7-14 Days
A32: Priority | B32: From SA | F32: From VIC | J32: From WA | N32: From QLD | R32: From NSW | V32: From TAS | Z32: From ACT
A33: Freight Size | B33: Metro | C33: Metro Outer | D33: Regional | F33: Metro | G33: Metro Outer | H33: Regional | J33: Metro | K33: Metro Outer | L33: Regional | N33: Metro | O33: Metro Outer | P33: Regional | R33: Metro | S33: Metro Outer | T33: Regional | V33: Metro | W33: Metro Outer | X33: Regional | Z33: Metro | AA33: Metro Outer | AB33: Regional
A34: Small | B34: 1-3 Days | C34: 2-5 Days | D34: 3-7 Days | F34: 1-3 Days | G34: 2-5 Days | H34: 3-7 Days | J34: 1-3 Days | K34: 3-7 Days | L34: 3-7 Days | N34: 1-2 Days | O34: 1-2 Days | P34: 2-5 Days | R34: 1-2 Days | S34: 1-2 Days | T34: 2-5 Days | V34: 1-2 Days | W34: 1-2 Days | X34: 2-5 Days | Z34: 1-2 Days | AA34: 1-2 Days | AB34: 2-5 Days
A35: Medium | B35: 1-3 Days | C35: 2-5 Days | D35: 3-7 Days | F35: 1-3 Days | G35: 2-5 Days | H35: 3-7 Days | J35: 1-3 Days | K35: 3-7 Days | L35: 3-7 Days | N35: 1-2 Days | O35: 1-2 Days | P35: 2-5 Days | R35: 1-2 Days | S35: 1-2 Days | T35: 2-5 Days | V35: 1-2 Days | W35: 1-2 Days | X35: 2-5 Days | Z35: 1-2 Days | AA35: 1-2 Days | AB35: 2-5 Days
A36: Large | B36: 1-3 Days | C36: 2-5 Days | D36: 3-7 Days | F36: 1-3 Days | G36: 2-5 Days | H36: 3-7 Days | J36: 3-7 Days | K36: 3-7 Days | L36: 5-10 Days | N36: 7-14 Days | O36: 7-14 Days | P36: 7-14 Days | R36: 7-14 Days | S36: 7-14 Days | T36: 7-14 Days | V36: 7-14 Days | W36: 7-14 Days | X36: 7-14 Days | Z36: 7-14 Days | AA36: 7-14 Days | AB36: 7-14 Days
A37: XL | V37: 7-14 Days | W37: 7-14 Days | X37: 7-14 Days | Z37: 7-14 Days | AA37: 7-14 Days | AB37: 7-14 Days
A38: XXL | V38: 7-14 Days | W38: 7-14 Days | X38: 7-14 Days | Z38: 7-14 Days | AA38: 7-14 Days | AB38: 7-14 Days
A39: Bulky | V39: 7-14 Days | W39: 7-14 Days | X39: 7-14 Days | Z39: 7-14 Days | AA39: 7-14 Days | AB39: 7-14 Days

Sheet QLD
A1: Freight Charges for QLD Orders
A3: Standard | B3: From QLD | F3: From VIC | J3: From SA | N3: From NSW | R3: From TAS | V3: From ACT | Z3: From WA
A4: Freight Size | B4: Metro | C4: Metro Outer | D4: Regional | F4: Metro | G4: Metro Outer | H4: Regional | J4: Metro | K4: Metro Outer | L4: Regional | N4: Metro | O4: Metro Outer | P4: Regional | R4: Metro | S4: Metro Outer | T4: Regional | V4: Metro | W4: Metro Outer | X4: Regional | Z4: Metro | AA4: Metro Outer | AB4: Regional
A5: Small | B5: ='Cost model'!M380 -> 8.5 | C5: ='Cost model'!M381 -> 14.5 | D5: ='Cost model'!M382 -> 18.5 | F5: ='Cost model'!M398 -> 15.5 | G5: ='Cost model'!M399 -> 17.5 | H5: ='Cost model'!M400 -> 20.5 | J5: ='Cost model'!M416 -> 16.5 | K5: ='Cost model'!M417 -> 18.5 | L5: ='Cost model'!M418 -> 21.5 | N5: ='Cost model'!M434 -> 13.5 | O5: ='Cost model'!M435 -> 15.5 | P5: ='Cost model'!M436 -> 19.5 | R5: ='Cost model'!M452 -> 13.5 | S5: ='Cost model'!M453 -> 16.5 | T5: ='Cost model'!M454 -> 22.5 | V5: ='Cost model'!M470 -> 19.5 | W5: ='Cost model'!M471 -> 35 | X5: ='Cost model'!M472 -> 35 | Z5: ='Cost model'!M488 -> 14.5 | AA5: ='Cost model'!M489 -> 26.5 | AB5: ='Cost model'!M490 -> 26.5
A6: Medium | B6: ='Cost model'!M383 -> 27.5 | C6: ='Cost model'!M384 -> 45 | D6: ='Cost model'!M385 -> 55 | F6: ='Cost model'!M401 -> 60 | G6: ='Cost model'!M402 -> 60 | H6: ='Cost model'!M403 -> 75 | J6: ='Cost model'!M419 -> 55 | K6: ='Cost model'!M420 -> 60 | L6: ='Cost model'!M421 -> 70 | N6: ='Cost model'!M437 -> 50 | O6: ='Cost model'!M438 -> 55 | P6: ='Cost model'!M439 -> 60 | R6: ='Cost model'!M455 -> 60 | S6: ='Cost model'!M456 -> 60 | T6: ='Cost model'!M457 -> 105 | V6: ='Cost model'!M473 -> 65 | W6: ='Cost model'!M474 -> 65 | X6: ='Cost model'!M475 -> 75 | Z6: ='Cost model'!M491 -> 55 | AA6: ='Cost model'!M492 -> 60 | AB6: ='Cost model'!M493 -> 70
A7: Large | B7: ='Cost model'!M386 -> 55 | C7: ='Cost model'!M387 -> 95 | D7: ='Cost model'!M388 -> 110 | F7: ='Cost model'!M404 -> 120 | G7: ='Cost model'!M405 -> 120 | H7: ='Cost model'!M406 -> 140 | J7: ='Cost model'!M422 -> 100 | K7: ='Cost model'!M423 -> 105 | L7: ='Cost model'!M424 -> 140 | N7: ='Cost model'!M440 -> 90 | O7: ='Cost model'!M441 -> 95 | P7: ='Cost model'!M442 -> 140 | R7: ='Cost model'!M458 -> 85 | S7: ='Cost model'!M459 -> 105 | T7: ='Cost model'!M460 -> 140 | V7: ='Cost model'!M476 -> 110 | W7: ='Cost model'!M477 -> 120 | X7: ='Cost model'!M478 -> 155 | Z7: ='Cost model'!M494 -> 95 | AA7: ='Cost model'!M495 -> 105 | AB7: ='Cost model'!M496 -> 140
A8: XL | B8: ='Cost model'!M389 -> 95 | C8: ='Cost model'!M390 -> 115 | D8: ='Cost model'!M391 -> 170 | F8: ='Cost model'!M407 -> 155 | G8: ='Cost model'!M408 -> 180 | H8: ='Cost model'!M409 -> 225 | J8: ='Cost model'!M425 -> 160 | K8: ='Cost model'!M426 -> 220 | L8: ='Cost model'!M427 -> 235 | N8: ='Cost model'!M443 -> 155 | O8: ='Cost model'!M444 -> 185 | P8: ='Cost model'!M445 -> 250 | R8: ='Cost model'!M461 -> 160 | S8: ='Cost model'!M462 -> 190 | T8: ='Cost model'!M463 -> 250 | V8: ='Cost model'!M479 -> 190 | W8: ='Cost model'!M480 -> 220 | X8: ='Cost model'!M481 -> 265 | Z8: ='Cost model'!M497 -> 160 | AA8: ='Cost model'!M498 -> 190 | AB8: ='Cost model'!M499 -> 230
