Workbook

Sheet Read me
A1: RRG Website Shipping · Australia · proposed rates
A2: Prepared 20 October 2026 from Roof Racks Galore order and carrier data. Same layout as "RRG Website Shipping OCT 2025": one tab per delivery state, a table for each warehouse the order ships from, Standard and Priority, Metro / Metro Outer / Regional.
A4: Settings (change the yellow cells; every price in the workbook updates)
A5: Freight margin on top of expected cost | B5: 0 | C5: 0% = break-even: on average the Standard charge covers what the carrier charges us for that size, zone and warehouse. 10% adds 10% on top of expected cost.
A6: Minimum Priority uplift over Standard ($) | B6: 5 | C6: Priority is at least this much more than Standard.
A7: Round prices up to the next $x.50 up to ($) | B7: 30 | C7: Below this, prices end in .50 (e.g. $12.50). Above it they round up to the next $5.
A9: Priority ÷ Standard ratio by size
A10: Small | B10: 1.34 | C10: Median of Priority ÷ Standard across the 2025 sheet, kept between 1.20 and 1.35 (Large was 2.1 and XL 1.0 in 2025 because those Standard prices were far below cost). Applied to every cell. Change these if you want a different Priority premium.
A11: Medium | B11: 1.26
A12: Large | B12: 1.35
A13: XL | B13: 1.2
A14: XXL | B14: 1.2
A17: How the prices are set
A18: 1. Each order is sized the way the website does it: every product gets a 1–5 score from its longest side, cubic weight (250 kg/m³) and actual weight, and the order takes its biggest product's size. See the Freight SIZE RULES tab.
A19: 2. Expected cost = what carriers charged us (plus 10% GST) on 21,585 orders, July 2025 to August 2026, matched in the sales, freight and carrier reports (Orders_Matched_All_3), that went from one warehouse as one consignment. Cost is the carrier's estimated cost in that file.
A20: 3. Costs are averaged after dropping the top and bottom 10% of orders in each group, so one-off surcharges don't set the price.
A21: 4. Each size × zone gets a national figure, separately for same-state and interstate deliveries. Each warehouse-to-state lane then gets a factor from its own orders (for example WA to VIC costs about 25% more than the interstate average). Lanes with few orders lean on the national figure; lanes with no orders use distance.
A22: 4b. Lane factors are worked out separately for Small, Medium and Large-and-up, kept between 0.6× and 1.6×, and interstate lanes with few orders lean more on distance (for example QLD–WA, with 13 orders from Wangara to QLD). A warehouse's own state is never priced above the cheapest other warehouse into that state (this mainly lowers ACT from Fyshwick, whose local orders mostly went StarTrack and TNT).
A23: 5. Where a lane has its own orders for a size and zone, those orders are blended in. Prices never go down from a smaller size to a larger one, or from Metro to Outer to Regional.
A24: 6. Standard = expected cost × (1 + freight margin), rounded up. Priority = Standard × the Priority ratio for its size (above), at least the minimum uplift, rounded up. We don't yet have enough priority shipments to cost Priority separately.
A25: 7. Delivery time frames are copied from the 2025 sheet, except that there is no 0–1 day Priority any more: those 30 cells (all same-state Metro deliveries) are now Priority 1–2 days and Standard 1–3 days (was 1–2 days).
A26: 8. One rate for interstate XXL to Metro Outer and Regional: these have one price only: Standard, set at what Priority would have cost, with no Priority option (the Priority price and time are left blank). The Standard cells are grey in the state tabs, use the Priority delivery times, and are marked "One rate" on the Cost model tab.
A28: What else changed from the 2025 sheet
A29: • The TAS tab now has a From SA table and the WA tab a From TAS table (both were missing).
... A38: • The Impact tab re-prices the same 21,585 orders under these rates so you can see the effect before changing the website.

Sheet Summary
A1: Summary
A2: Re-pricing the 21,585 matched single-shipment orders (Impact tab) under the new rates. Updates when you change the settings on Read me.
B4: Orders | C4: We charged | D4: Cost us | E4: Charged − cost | F4: New rates would charge | G4: New − cost
A5: All orders | B5: =COUNTA(Impact!$A$2:$A$21586) -> 21585 | C5: =SUM(Impact!$G$2:$G$21586) -> 453660.59 | D5: =SUM(Impact!$H$2:$H$21586) -> 784190.19 | E5: =C5-D5 -> -330529.6 | F5: =SUM(Impact!$J$2:$J$21586) -> 781646.5 | G5: =F5-D5 -> -2543.69
A7: By size
A8: Small | B8: =COUNTIF(Impact!$D$2:$D$21586,"Small") -> 10698 | C8: =SUMIF(Impact!$D$2:$D$21586,"Small",Impact!$G$2:$G$21586) -> 154197.38 | D8: =SUMIF(Impact!$D$2:$D$21586,"Small",Impact!$H$2:$H$21586) -> 164358.85 | E8: =C8-D8 -> -10161.47 | F8: =SUMIF(Impact!$D$2:$D$21586,"Small",Impact!$J$2:$J$21586) -> 151295 | G8: =F8-D8 -> -13063.85
A9: Medium | B9: =COUNTIF(Impact!$D$2:$D$21586,"Medium") -> 8330 | C9: =SUMIF(Impact!$D$2:$D$21586,"Medium",Impact!$G$2:$G$21586) -> 158789.23 | D9: =SUMIF(Impact!$D$2:$D$21586,"Medium",Impact!$H$2:$H$21586) -> 324148.17 | E9: =C9-D9 -> -165358.94 | F9: =SUMIF(Impact!$D$2:$D$21586,"Medium",Impact!$J$2:$J$21586) -> 344448.5 | G9: =F9-D9 -> 20300.33
A10: Large | B10: =COUNTIF(Impact!$D$2:$D$21586,"Large") -> 1221 | C10: =SUMIF(Impact!$D$2:$D$21586,"Large",Impact!$G$2:$G$21586) -> 47138.03 | D10: =SUMIF(Impact!$D$2:$D$21586,"Large",Impact!$H$2:$H$21586) -> 100142.97 | E10: =C10-D10 -> -53004.94 | F10: =SUMIF(Impact!$D$2:$D$21586,"Large",Impact!$J$2:$J$21586) -> 96978 | G10: =F10-D10 -> -3164.97
A11: XL | B11: =COUNTIF(Impact!$D$2:$D$21586,"XL") -> 1062 | C11: =SUMIF(Impact!$D$2:$D$21586,"XL",Impact!$G$2:$G$21586) -> 67921.46 | D11: =SUMIF(Impact!$D$2:$D$21586,"XL",Impact!$H$2:$H$21586) -> 144957.79 | E11: =C11-D11 -> -77036.33 | F11: =SUMIF(Impact!$D$2:$D$21586,"XL",Impact!$J$2:$J$21586) -> 138820 | G11: =F11-D11 -> -6137.79
A12: XXL | B12: =COUNTIF(Impact!$D$2:$D$21586,"XXL") -> 274 | C12: =SUMIF(Impact!$D$2:$D$21586,"XXL",Impact!$G$2:$G$21586) -> 25614.49 | D12: =SUMIF(Impact!$D$2:$D$21586,"XXL",Impact!$H$2:$H$21586) -> 50582.41 | E12: =C12-D12 -> -24967.92 | F12: =SUMIF(Impact!$D$2:$D$21586,"XXL",Impact!$J$2:$J$21586) -> 50105 | G12: =F12-D12 -> -477.41
A14: By zone
A15: Metro | B15: =COUNTIF(Impact!$C$2:$C$21586,"Metro") -> 9973 | C15: =SUMIF(Impact!$C$2:$C$21586,"Metro",Impact!$G$2:$G$21586) -> 153909.4 | D15: =SUMIF(Impact!$C$2:$C$21586,"Metro",Impact!$H$2:$H$21586) -> 275798.06 | E15: =C15-D15 -> -121888.66 | F15: =SUMIF(Impact!$C$2:$C$21586,"Metro",Impact!$J$2:$J$21586) -> 272077.5 | G15: =F15-D15 -> -3720.56
A16: Metro Outer | B16: =COUNTIF(Impact!$C$2:$C$21586,"Metro Outer") -> 6495 | C16: =SUMIF(Impact!$C$2:$C$21586,"Metro Outer",Impact!$G$2:$G$21586) -> 132035.83 | D16: =SUMIF(Impact!$C$2:$C$21586,"Metro Outer",Impact!$H$2:$H$21586) -> 247958.21 | E16: =C16-D16 -> -115922.38 | F16: =SUMIF(Impact!$C$2:$C$21586,"Metro Outer",Impact!$J$2:$J$21586) -> 252989 | G16: =F16-D16 -> 5030.79
A17: Regional | B17: =COUNTIF(Impact!$C$2:$C$21586,"Regional") -> 5117 | C17: =SUMIF(Impact!$C$2:$C$21586,"Regional",Impact!$G$2:$G$21586) -> 167715.36 | D17: =SUMIF(Impact!$C$2:$C$21586,"Regional",Impact!$H$2:$H$21586) -> 260433.92 | E17: =C17-D17 -> -92718.56 | F17: =SUMIF(Impact!$C$2:$C$21586,"Regional",Impact!$J$2:$J$21586) -> 256580 | G17: =F17-D17 -> -3853.92
A19: By warehouse
A20: QLD · Brendale | B20: =COUNTIF(Impact!$B$2:$B$21586,"QLD") -> 6038 | C20: =SUMIF(Impact!$B$2:$B$21586,"QLD",Impact!$G$2:$G$21586) -> 123663.46 | D20: =SUMIF(Impact!$B$2:$B$21586,"QLD",Impact!$H$2:$H$21586) -> 223158.1 | E20: =C20-D20 -> -99494.64 | F20: =SUMIF(Impact!$B$2:$B$21586,"QLD",Impact!$J$2:$J$21586) -> 223463.5 | G20: =F20-D20 -> 305.4
A21: NSW · Moorebank | B21: =COUNTIF(Impact!$B$2:$B$21586,"NSW") -> 6243 | C21: =SUMIF(Impact!$B$2:$B$21586,"NSW",Impact!$G$2:$G$21586) -> 127256.18 | D21: =SUMIF(Impact!$B$2:$B$21586,"NSW",Impact!$H$2:$H$21586) -> 212864.15 | E21: =C21-D21 -> -85607.97 | F21: =SUMIF(Impact!$B$2:$B$21586,"NSW",Impact!$J$2:$J$21586) -> 214090.5 | G21: =F21-D21 -> 1226.35
A22: VIC · Campbellfield | B22: =COUNTIF(Impact!$B$2:$B$21586,"VIC") -> 4431 | C22: =SUMIF(Impact!$B$2:$B$21586,"VIC",Impact!$G$2:$G$21586) -> 90737.95 | D22: =SUMIF(Impact!$B$2:$B$21586,"VIC",Impact!$H$2:$H$21586) -> 153924.38 | E22: =C22-D22 -> -63186.43 | F22: =SUMIF(Impact!$B$2:$B$21586,"VIC",Impact!$J$2:$J$21586) -> 155774 | G22: =F22-D22 -> 1849.62
A23: SA · Adelaide | B23: =COUNTIF(Impact!$B$2:$B$21586,"SA") -> 1922 | C23: =SUMIF(Impact!$B$2:$B$21586,"SA",Impact!$G$2:$G$21586) -> 44535.35 | D23: =SUMIF(Impact!$B$2:$B$21586,"SA",Impact!$H$2:$H$21586) -> 67861.06 | E23: =C23-D23 -> -23325.71 | F23: =SUMIF(Impact!$B$2:$B$21586,"SA",Impact!$J$2:$J$21586) -> 67932 | G23: =F23-D23 -> 70.94
A24: WA · Wangara | B24: =COUNTIF(Impact!$B$2:$B$21586,"WA") -> 2467 | C24: =SUMIF(Impact!$B$2:$B$21586,"WA",Impact!$G$2:$G$21586) -> 56720.9 | D24: =SUMIF(Impact!$B$2:$B$21586,"WA",Impact!$H$2:$H$21586) -> 103369.45 | E24: =C24-D24 -> -46648.55 | F24: =SUMIF(Impact!$B$2:$B$21586,"WA",Impact!$J$2:$J$21586) -> 100341.5 | G24: =F24-D24 -> -3027.95
A25: TAS · Moonah | B25: =COUNTIF(Impact!$B$2:$B$21586,"TAS") -> 269 | C25: =SUMIF(Impact!$B$2:$B$21586,"TAS",Impact!$G$2:$G$21586) -> 6009.22 | D25: =SUMIF(Impact!$B$2:$B$21586,"TAS",Impact!$H$2:$H$21586) -> 13260.62 | E25: =C25-D25 -> -7251.4 | F25: =SUMIF(Impact!$B$2:$B$21586,"TAS",Impact!$J$2:$J$21586) -> 11407 | G25: =F25-D25 -> -1853.62
A26: ACT · Fyshwick | B26: =COUNTIF(Impact!$B$2:$B$21586,"ACT") -> 215 | C26: =SUMIF(Impact!$B$2:$B$21586,"ACT",Impact!$G$2:$G$21586) -> 4737.53 | D26: =SUMIF(Impact!$B$2:$B$21586,"ACT",Impact!$H$2:$H$21586) -> 9752.43 | E26: =C26-D26 -> -5014.9 | F26: =SUMIF(Impact!$B$2:$B$21586,"ACT",Impact!$J$2:$J$21586) -> 8638 | G26: =F26-D26 -> -1114.43
A28: Typical price per order, Standard (median of each tab's same-state table)
A29: Size | B29: Metro 2025 | C29: Metro new | D29: Outer 2025 | E29: Outer new | F29: Regional 2025 | G29: Regional new
A30: Small | B30: 9.5 | C30: =MEDIAN('Cost model'!M62,'Cost model'!M167,'Cost model'!M317,'Cost model'!M422,'Cost model'!M527,'Cost model'!M632,'Cost model'!M737) -> 9.5 | D30: 12.5 | E30: =MEDIAN('Cost model'!M63,'Cost model'!M168,'Cost model'!M318,'Cost model'!M423,'Cost model'!M528,'Cost model'!M633,'Cost model'!M738) -> 13.5 | F30: 17.5 | G30: =MEDIAN('Cost model'!M64,'Cost model'!M169,'Cost model'!M319,'Cost model'!M424,'Cost model'!M529,'Cost model'!M634,'Cost model'!M739) -> 16.5
A31: Medium | B31: 9.5 | C31: =MEDIAN('Cost model'!M65,'Cost model'!M170,'Cost model'!M320,'Cost model'!M425,'Cost model'!M530,'Cost model'!M635,'Cost model'!M740) -> 25.5 | D31: 12.5 | E31: =MEDIAN('Cost model'!M66,'Cost model'!M171,'Cost model'!M321,'Cost model'!M426,'Cost model'!M531,'Cost model'!M636,'Cost model'!M741) -> 40 | F31: 19.5 | G31: =MEDIAN('Cost model'!M67,'Cost model'!M172,'Cost model'!M322,'Cost model'!M427,'Cost model'!M532,'Cost model'!M637,'Cost model'!M742) -> 45
A32: Large | B32: 19 | C32: =MEDIAN('Cost model'!M68,'Cost model'!M173,'Cost model'!M323,'Cost model'!M428,'Cost model'!M533,'Cost model'!M638,'Cost model'!M743) -> 55 | D32: 24.5 | E32: =MEDIAN('Cost model'!M69,'Cost model'!M174,'Cost model'!M324,'Cost model'!M429,'Cost model'!M534,'Cost model'!M639,'Cost model'!M744) -> 70 | F32: 50 | G32: =MEDIAN('Cost model'!M70,'Cost model'!M175,'Cost model'!M325,'Cost model'!M430,'Cost model'!M535,'Cost model'!M640,'Cost model'!M745) -> 95
A33: XL | B33: 25 | C33: =MEDIAN('Cost model'!M71,'Cost model'!M176,'Cost model'!M326,'Cost model'!M431,'Cost model'!M536,'Cost model'!M641,'Cost model'!M746) -> 100 | D33: 45 | E33: =MEDIAN('Cost model'!M72,'Cost model'!M177,'Cost model'!M327,'Cost model'!M432,'Cost model'!M537,'Cost model'!M642,'Cost model'!M747) -> 130 | F33: 85 | G33: =MEDIAN('Cost model'!M73,'Cost model'!M178,'Cost model'!M328,'Cost model'!M433,'Cost model'!M538,'Cost model'!M643,'Cost model'!M748) -> 165
A34: XXL | B34: 45 | C34: =MEDIAN('Cost model'!M74,'Cost model'!M179,'Cost model'!M329,'Cost model'!M434,'Cost model'!M539,'Cost model'!M644,'Cost model'!M749) -> 135 | D34: 85 | E34: =MEDIAN('Cost model'!M75,'Cost model'!M180,'Cost model'!M330,'Cost model'!M435,'Cost model'!M540,'Cost model'!M645,'Cost model'!M750) -> 180 | F34: 250 | G34: =MEDIAN('Cost model'!M76,'Cost model'!M181,'Cost model'!M331,'Cost model'!M436,'Cost model'!M541,'Cost model'!M646,'Cost model'!M751) -> 230
A36: Option: split Medium at 1.05 m (what Medium orders actually cost us, incl. GST, trimmed average)
B37: Orders | C37: Metro | D37: Outer metro | E37: Regional
A38: Medium up to 1.05 m, same state | B38: 1887 | C38: 11.95 | D38: 20.92 | E38: 27.1
A39: Medium over 1.05 m, same state | B39: 4247 | C39: 30.64 | D39: 43.65 | E39: 50.85
A40: Medium up to 1.05 m, interstate | B40: 687 | C40: 22.85 | D40: 25.81 | E40: 35.17
A41: Medium over 1.05 m, interstate | B41: 1560 | C41: 49.42 | D41: 55.37 | E41: 61.01
A42: Most Medium orders under 1.05 m can go Australia Post. Splitting Medium would let the website keep a low price for those and charge the long ones what StarTrack costs. It needs a 6th size on the website, so it isn't applied in the state tabs.

Sheet ACT
A1: Freight Charges for ACT Orders
A3: Standard | B3: From QLD | F3: From VIC | J3: From SA | N3: From NSW | R3: From ACT | V3: From TAS | Z3: From WA
A4: Freight Size | B4: Metro | C4: Metro Outer | D4: Regional | F4: Metro | G4: Metro Outer | H4: Regional | J4: Metro | K4: Metro Outer | L4: Regional | N4: Metro | O4: Metro Outer | P4: Regional | R4: Metro | S4: Metro Outer | T4: Regional | V4: Metro | W4: Metro Outer | X4: Regional | Z4: Metro | AA4: Metro Outer | AB4: Regional
A5: Small | B5: ='Cost model'!M2 -> 14.5 | C5: ='Cost model'!M3 -> 16.5 | D5: ='Cost model'!M4 -> 20.5 | F5: ='Cost model'!M17 -> 12.5 | G5: ='Cost model'!M18 -> 13.5 | H5: ='Cost model'!M19 -> 16.5 | J5: ='Cost model'!M32 -> 15.5 | K5: ='Cost model'!M33 -> 18.5 | L5: ='Cost model'!M34 -> 22.5 | N5: ='Cost model'!M47 -> 12.5 | O5: ='Cost model'!M48 -> 14.5 | P5: ='Cost model'!M49 -> 17.5 | R5: ='Cost model'!M62 -> 12.5 | S5: ='Cost model'!M63 -> 13.5 | T5: ='Cost model'!M64 -> 16.5 | V5: ='Cost model'!M77 -> 13.5 | W5: ='Cost model'!M78 -> 15.5 | X5: ='Cost model'!M79 -> 19.5 | Z5: ='Cost model'!M92 -> 14.5 | AA5: ='Cost model'!M93 -> 17.5 | AB5: ='Cost model'!M94 -> 21.5
A6: Medium | B6: ='Cost model'!M5 -> 35 | C6: ='Cost model'!M6 -> 40 | D6: ='Cost model'!M7 -> 45 | F6: ='Cost model'!M20 -> 35 | G6: ='Cost model'!M21 -> 40 | H6: ='Cost model'!M22 -> 45 | J6: ='Cost model'!M35 -> 45 | K6: ='Cost model'!M36 -> 50 | L6: ='Cost model'!M37 -> 55 | N6: ='Cost model'!M50 -> 40 | O6: ='Cost model'!M51 -> 50 | P6: ='Cost model'!M52 -> 55 | R6: ='Cost model'!M65 -> 35 | S6: ='Cost model'!M66 -> 40 | T6: ='Cost model'!M67 -> 45 | V6: ='Cost model'!M80 -> 40 | W6: ='Cost model'!M81 -> 50 | X6: ='Cost model'!M82 -> 55 | Z6: ='Cost model'!M95 -> 50 | AA6: ='Cost model'!M96 -> 55 | AB6: ='Cost model'!M97 -> 60
A7: Large | B7: ='Cost model'!M8 -> 75 | C7: ='Cost model'!M9 -> 85 | D7: ='Cost model'!M10 -> 110 | F7: ='Cost model'!M23 -> 60 | G7: ='Cost model'!M24 -> 70 | H7: ='Cost model'!M25 -> 95 | J7: ='Cost model'!M38 -> 80 | K7: ='Cost model'!M39 -> 90 | L7: ='Cost model'!M40 -> 120 | N7: ='Cost model'!M53 -> 75 | O7: ='Cost model'!M54 -> 85 | P7: ='Cost model'!M55 -> 115 | R7: ='Cost model'!M68 -> 60 | S7: ='Cost model'!M69 -> 70 | T7: ='Cost model'!M70 -> 95 | V7: ='Cost model'!M83 -> 70 | W7: ='Cost model'!M84 -> 85 | X7: ='Cost model'!M85 -> 110 | Z7: ='Cost model'!M98 -> 75 | AA7: ='Cost model'!M99 -> 90 | AB7: ='Cost model'!M100 -> 120
A8: XL | B8: ='Cost model'!M11 -> 120 | C8: ='Cost model'!M12 -> 150 | D8: ='Cost model'!M13 -> 195 | F8: ='Cost model'!M26 -> 105 | G8: ='Cost model'!M27 -> 130 | H8: ='Cost model'!M28 -> 165 | J8: ='Cost model'!M41 -> 125 | K8: ='Cost model'!M42 -> 165 | L8: ='Cost model'!M43 -> 210 | N8: ='Cost model'!M56 -> 130 | O8: ='Cost model'!M57 -> 160 | P8: ='Cost model'!M58 -> 200 | R8: ='Cost model'!M71 -> 105 | S8: ='Cost model'!M72 -> 130 | T8: ='Cost model'!M73 -> 165 | V8: ='Cost model'!M86 -> 120 | W8: ='Cost model'!M87 -> 150 | X8: ='Cost model'!M88 -> 190 | Z8: ='Cost model'!M101 -> 130 | AA8: ='Cost model'!M102 -> 165 | AB8: ='Cost model'!M103 -> 210
A9: XXL | B9: ='Cost model'!M14 -> 160 | C9: ='Cost model'!M15 -> 265 | D9: ='Cost model'!M16 -> 320 | F9: ='Cost model'!M29 -> 135 | G9: ='Cost model'!M30 -> 230 | H9: ='Cost model'!M31 -> 280 | J9: ='Cost model'!M44 -> 170 | K9: ='Cost model'!M45 -> 290 | L9: ='Cost model'!M46 -> 345 | N9: ='Cost model'!M59 -> 170 | O9: ='Cost model'!M60 -> 280 | P9: ='Cost model'!M61 -> 330 | R9: ='Cost model'!M74 -> 135 | S9: ='Cost model'!M75 -> 190 | T9: ='Cost model'!M76 -> 230 | V9: ='Cost model'!M89 -> 160 | W9: ='Cost model'!M90 -> 265 | X9: ='Cost model'!M91 -> 320 | Z9: ='Cost model'!M104 -> 170 | AA9: ='Cost model'!M105 -> 290 | AB9: ='Cost model'!M106 -> 345
A11: Priority | B11: From QLD | F11: From VIC | J11: From SA | N11: From NSW | R11: From ACT | V11: From TAS | Z11: From WA
A12: Freight Size | B12: Metro | C12: Metro Outer | D12: Regional | F12: Metro | G12: Metro Outer | H12: Regional | J12: Metro | K12: Metro Outer | L12: Regional | N12: Metro | O12: Metro Outer | P12: Regional | R12: Metro | S12: Metro Outer | T12: Regional | V12: Metro | W12: Metro Outer | X12: Regional | Z12: Metro | AA12: Metro Outer | AB12: Regional
A13: Small | B13: ='Cost model'!N2 -> 19.5 | C13: ='Cost model'!N3 -> 22.5 | D13: ='Cost model'!N4 -> 27.5 | F13: ='Cost model'!N17 -> 17.5 | G13: ='Cost model'!N18 -> 18.5 | H13: ='Cost model'!N19 -> 22.5 | J13: ='Cost model'!N32 -> 21.5 | K13: ='Cost model'!N33 -> 25.5 | L13: ='Cost model'!N34 -> 35 | N13: ='Cost model'!N47 -> 17.5 | O13: ='Cost model'!N48 -> 19.5 | P13: ='Cost model'!N49 -> 23.5 | R13: ='Cost model'!N62 -> 17.5 | S13: ='Cost model'!N63 -> 18.5 | T13: ='Cost model'!N64 -> 22.5 | V13: ='Cost model'!N77 -> 18.5 | W13: ='Cost model'!N78 -> 21.5 | X13: ='Cost model'!N79 -> 26.5 | Z13: ='Cost model'!N92 -> 19.5 | AA13: ='Cost model'!N93 -> 23.5 | AB13: ='Cost model'!N94 -> 29.5
A14: Medium | B14: ='Cost model'!N5 -> 45 | C14: ='Cost model'!N6 -> 55 | D14: ='Cost model'!N7 -> 60 | F14: ='Cost model'!N20 -> 45 | G14: ='Cost model'!N21 -> 55 | H14: ='Cost model'!N22 -> 60 | J14: ='Cost model'!N35 -> 60 | K14: ='Cost model'!N36 -> 65 | L14: ='Cost model'!N37 -> 70 | N14: ='Cost model'!N50 -> 55 | O14: ='Cost model'!N51 -> 65 | P14: ='Cost model'!N52 -> 70 | R14: ='Cost model'!N65 -> 45 | S14: ='Cost model'!N66 -> 55 | T14: ='Cost model'!N67 -> 60 | V14: ='Cost model'!N80 -> 55 | W14: ='Cost model'!N81 -> 65 | X14: ='Cost model'!N82 -> 70 | Z14: ='Cost model'!N95 -> 65 | AA14: ='Cost model'!N96 -> 70 | AB14: ='Cost model'!N97 -> 80
A15: Large | B15: ='Cost model'!N8 -> 105 | C15: ='Cost model'!N9 -> 115 | D15: ='Cost model'!N10 -> 150 | F15: ='Cost model'!N23 -> 85 | G15: ='Cost model'!N24 -> 95 | H15: ='Cost model'!N25 -> 130 | J15: ='Cost model'!N38 -> 110 | K15: ='Cost model'!N39 -> 125 | L15: ='Cost model'!N40 -> 165 | N15: ='Cost model'!N53 -> 105 | O15: ='Cost model'!N54 -> 115 | P15: ='Cost model'!N55 -> 160 | R15: ='Cost model'!N68 -> 85 | S15: ='Cost model'!N69 -> 95 | T15: ='Cost model'!N70 -> 130 | V15: ='Cost model'!N83 -> 95 | W15: ='Cost model'!N84 -> 115 | X15: ='Cost model'!N85 -> 150 | Z15: ='Cost model'!N98 -> 105 | AA15: ='Cost model'!N99 -> 125 | AB15: ='Cost model'!N100 -> 165
A16: XL | B16: ='Cost model'!N11 -> 145 | C16: ='Cost model'!N12 -> 180 | D16: ='Cost model'!N13 -> 235 | F16: ='Cost model'!N26 -> 130 | G16: ='Cost model'!N27 -> 160 | H16: ='Cost model'!N28 -> 200 | J16: ='Cost model'!N41 -> 150 | K16: ='Cost model'!N42 -> 200 | L16: ='Cost model'!N43 -> 255 | N16: ='Cost model'!N56 -> 160 | O16: ='Cost model'!N57 -> 195 | P16: ='Cost model'!N58 -> 240 | R16: ='Cost model'!N71 -> 130 | S16: ='Cost model'!N72 -> 160 | T16: ='Cost model'!N73 -> 200 | V16: ='Cost model'!N86 -> 145 | W16: ='Cost model'!N87 -> 180 | X16: ='Cost model'!N88 -> 230 | Z16: ='Cost model'!N101 -> 160 | AA16: ='Cost model'!N102 -> 200 | AB16: ='Cost model'!N103 -> 255
A17: XXL | B17: ='Cost model'!N14 -> 195 | F17: ='Cost model'!N29 -> 165 | J17: ='Cost model'!N44 -> 205 | N17: ='Cost model'!N59 -> 205 | R17: ='Cost model'!N74 -> 165 | S17: ='Cost model'!N75 -> 230 | T17: ='Cost model'!N76 -> 280 | V17: ='Cost model'!N89 -> 195 | Z17: ='Cost model'!N104 -> 205
A19: Delivery time frames for ACT Orders
A21: Standard | B21: From QLD | F21: From VIC | J21: From SA | N21: From NSW | R21: From ACT | V21: From TAS | Z21: From WA
A22: Freight Size | B22: Metro | C22: Metro Outer | D22: Regional | F22: Metro | G22: Metro Outer | H22: Regional | J22: Metro | K22: Metro Outer | L22: Regional | N22: Metro | O22: Metro Outer | P22: Regional | R22: Metro | S22: Metro Outer | T22: Regional | V22: Metro | W22: Metro Outer | X22: Regional | Z22: Metro | AA22: Metro Outer | AB22: Regional
A23: Small | B23: 2-5 Days | C23: 2-5 Days | D23: 3-7 Days | F23: 2-5 Days | G23: 2-5 Days | H23: 2-5 Days | J23: 2-5 Days | K23: 2-5 Days | L23: 2-5 Days | N23: 2-5 Days | O23: 2-5 Days | P23: 3-7 Days | R23: 1-3 Days | S23: 1-3 Days | T23: 2-5 Days | V23: 7-14 Days | W23: 7-14 Days | X23: 7-14 Days | Z23: 7-14 Days | AA23: 7-14 Days | AB23: 7-14 Days
A24: Medium | B24: 2-5 Days | C24: 2-5 Days | D24: 3-7 Days | F24: 2-5 Days | G24: 2-5 Days | H24: 2-5 Days | J24: 2-5 Days | K24: 2-5 Days | L24: 2-5 Days | N24: 2-5 Days | O24: 2-5 Days | P24: 3-7 Days | R24: 1-3 Days | S24: 1-3 Days | T24: 2-5 Days | V24: 7-14 Days | W24: 7-14 Days | X24: 7-14 Days | Z24: 7-14 Days | AA24: 7-14 Days | AB24: 7-14 Days
A25: Large | B25: 3-7 Days | C25: 3-7 Days | D25: 5-10 Days | F25: 3-7 Days | G25: 3-7 Days | H25: 5-10 Days | J25: 3-7 Days | K25: 3-7 Days | L25: 5-10 Days | N25: 3-7 Days | O25: 3-7 Days | P25: 5-10 Days | R25: 1-3 Days | S25: 1-3 Days | T25: 3-7 Days | V25: 7-14 Days | W25: 7-14 Days | X25: 7-14 Days | Z25: 7-14 Days | AA25: 7-14 Days | AB25: 7-14 Days
A26: XL | B26: 5-10 Days | C26: 5-10 Days | D26: 5-10 Days | F26: 5-10 Days | G26: 5-10 Days | H26: 5-10 Days | J26: 5-10 Days | K26: 5-10 Days | L26: 5-10 Days | N26: 5-10 Days | O26: 5-10 Days | P26: 5-10 Days | R26: 1-3 Days | S26: 1-3 Days | T26: 5-10 Days | V26: 7-14 Days | W26: 7-14 Days | X26: 7-14 Days | Z26: 7-14 Days | AA26: 7-14 Days | AB26: 7-14 Days
A27: XXL | B27: 5-10 Days | C27: 3-7 Days | D27: 5-10 Days | F27: 5-10 Days | G27: 3-7 Days | H27: 5-10 Days | J27: 5-10 Days | K27: 3-7 Days | L27: 5-10 Days | N27: 5-10 Days | O27: 3-7 Days | P27: 5-10 Days | R27: 1-3 Days | S27: 1-3 Days | T27: 5-10 Days | V27: 7-14 Days | W27: 7-14 Days | X27: 7-14 Days | Z27: 7-14 Days | AA27: 7-14 Days | AB27: 7-14 Days
A29: Priority | B29: From QLD | F29: From VIC | J29: From SA | N29: From NSW | R29: From ACT | V29: From TAS | Z29: From WA
A30: Freight Size | B30: Metro | C30: Metro Outer | D30: Regional | F30: Metro | G30: Metro Outer | H30: Regional | J30: Metro | K30: Metro Outer | L30: Regional | N30: Metro | O30: Metro Outer | P30: Regional | R30: Metro | S30: Metro Outer | T30: Regional | V30: Metro | W30: Metro Outer | X30: Regional | Z30: Metro | AA30: Metro Outer | AB30: Regional
A31: Small | B31: 1-2 Days | C31: 1-2 Days | D31: 2-5 Days | F31: 1-2 Days | G31: 1-2 Days | H31: 2-5 Days | J31: 1-2 Days | K31: 1-2 Days | L31: 2-5 Days | N31: 1-2 Days | O31: 1-2 Days | P31: 2-5 Days | R31: 1-2 Days | S31: 1-2 Days | T31: 1-3 Days | V31: 1-2 Days | W31: 1-2 Days | X31: 2-5 Days | Z31: 1-2 Days | AA31: 1-2 Days | AB31: 2-5 Days
A32: Medium | B32: 1-2 Days | C32: 1-2 Days | D32: 2-5 Days | F32: 1-2 Days | G32: 1-2 Days | H32: 2-5 Days | J32: 1-2 Days | K32: 1-2 Days | L32: 2-5 Days | N32: 1-2 Days | O32: 1-2 Days | P32: 2-5 Days | R32: 1-2 Days | S32: 1-2 Days | T32: 1-3 Days | V32: 1-2 Days | W32: 1-2 Days | X32: 2-5 Days | Z32: 1-2 Days | AA32: 1-2 Days | AB32: 2-5 Days
A33: Large | B33: 2-5 Days | C33: 2-5 Days | D33: 5-10 Days | F33: 2-5 Days | G33: 2-5 Days | H33: 5-10 Days | J33: 2-5 Days | K33: 2-5 Days | L33: 5-10 Days | N33: 2-5 Days | O33: 2-5 Days | P33: 5-10 Days | R33: 1-2 Days | S33: 1-2 Days | T33: 2-7 Days | V33: 7-14 Days | W33: 7-14 Days | X33: 7-14 Days | Z33: 7-14 Days | AA33: 7-14 Days | AB33: 7-14 Days
A34: XL | B34: 3-7 Days | C34: 3-7 Days | D34: 5-10 Days | F34: 3-7 Days | G34: 3-7 Days | H34: 5-10 Days | J34: 3-7 Days | K34: 3-7 Days | L34: 5-10 Days | N34: 3-7 Days | O34: 3-7 Days | P34: 5-10 Days | R34: 1-2 Days | S34: 1-2 Days | T34: 2-7 Days | V34: 7-14 Days | W34: 7-14 Days | X34: 7-14 Days | Z34: 7-14 Days | AA34: 7-14 Days | AB34: 7-14 Days
A35: XXL | B35: 3-7 Days | F35: 3-7 Days | J35: 3-7 Days | N35: 3-7 Days | R35: 1-2 Days | S35: 1-2 Days | T35: 2-7 Days | V35: 7-14 Days | Z35: 7-14 Days

Sheet NSW
A1: Freight Charges for NSW Orders
A3: Standard | B3: From QLD | F3: From VIC | J3: From SA | N3: From WA | R3: From NSW | V3: From TAS | Z3: From ACT
A4: Freight Size | B4: Metro | C4: Metro Outer | D4: Regional | F4: Metro | G4: Metro Outer | H4: Regional | J4: Metro | K4: Metro Outer | L4: Regional | N4: Metro | O4: Metro Outer | P4: Regional | R4: Metro | S4: Metro Outer | T4: Regional | V4: Metro | W4: Metro Outer | X4: Regional | Z4: Metro | AA4: Metro Outer | AB4: Regional
A5: Small | B5: ='Cost model'!M107 -> 12.5 | C5: ='Cost model'!M108 -> 15.5 | D5: ='Cost model'!M109 -> 18.5 | F5: ='Cost model'!M122 -> 13.5 | G5: ='Cost model'!M123 -> 16.5 | H5: ='Cost model'!M124 -> 21.5 | J5: ='Cost model'!M137 -> 13.5 | K5: ='Cost model'!M138 -> 16.5 | L5: ='Cost model'!M139 -> 19.5 | N5: ='Cost model'!M152 -> 13.5 | O5: ='Cost model'!M153 -> 15.5 | P5: ='Cost model'!M154 -> 20.5 | R5: ='Cost model'!M167 -> 8.5 | S5: ='Cost model'!M168 -> 13.5 | T5: ='Cost model'!M169 -> 18.5 | V5: ='Cost model'!M182 -> 14.5 | W5: ='Cost model'!M183 -> 17.5 | X5: ='Cost model'!M184 -> 24.5 | Z5: ='Cost model'!M197 -> 20.5 | AA5: ='Cost model'!M198 -> 20.5 | AB5: ='Cost model'!M199 -> 23.5
A6: Medium | B6: ='Cost model'!M110 -> 40 | C6: ='Cost model'!M111 -> 45 | D6: ='Cost model'!M112 -> 50 | F6: ='Cost model'!M125 -> 40 | G6: ='Cost model'!M126 -> 45 | H6: ='Cost model'!M127 -> 50 | J6: ='Cost model'!M140 -> 40 | K6: ='Cost model'!M141 -> 50 | L6: ='Cost model'!M142 -> 55 | N6: ='Cost model'!M155 -> 50 | O6: ='Cost model'!M156 -> 60 | P6: ='Cost model'!M157 -> 65 | R6: ='Cost model'!M170 -> 25.5 | S6: ='Cost model'!M171 -> 40 | T6: ='Cost model'!M172 -> 45 | V6: ='Cost model'!M185 -> 50 | W6: ='Cost model'!M186 -> 60 | X6: ='Cost model'!M187 -> 65 | Z6: ='Cost model'!M200 -> 45 | AA6: ='Cost model'!M201 -> 55 | AB6: ='Cost model'!M202 -> 65
A7: Large | B7: ='Cost model'!M113 -> 65 | C7: ='Cost model'!M114 -> 80 | D7: ='Cost model'!M115 -> 105 | F7: ='Cost model'!M128 -> 65 | G7: ='Cost model'!M129 -> 75 | H7: ='Cost model'!M130 -> 100 | J7: ='Cost model'!M143 -> 70 | K7: ='Cost model'!M144 -> 85 | L7: ='Cost model'!M145 -> 115 | N7: ='Cost model'!M158 -> 90 | O7: ='Cost model'!M159 -> 100 | P7: ='Cost model'!M160 -> 135 | R7: ='Cost model'!M173 -> 60 | S7: ='Cost model'!M174 -> 70 | T7: ='Cost model'!M175 -> 75 | V7: ='Cost model'!M188 -> 80 | W7: ='Cost model'!M189 -> 85 | X7: ='Cost model'!M190 -> 125 | Z7: ='Cost model'!M203 -> 65 | AA7: ='Cost model'!M204 -> 75 | AB7: ='Cost model'!M205 -> 105
A8: XL | B8: ='Cost model'!M116 -> 120 | C8: ='Cost model'!M117 -> 135 | D8: ='Cost model'!M118 -> 180 | F8: ='Cost model'!M131 -> 95 | G8: ='Cost model'!M132 -> 145 | H8: ='Cost model'!M133 -> 160 | J8: ='Cost model'!M146 -> 115 | K8: ='Cost model'!M147 -> 150 | L8: ='Cost model'!M148 -> 190 | N8: ='Cost model'!M161 -> 145 | O8: ='Cost model'!M162 -> 185 | P8: ='Cost model'!M163 -> 240 | R8: ='Cost model'!M176 -> 95 | S8: ='Cost model'!M177 -> 110 | T8: ='Cost model'!M178 -> 145 | V8: ='Cost model'!M191 -> 130 | W8: ='Cost model'!M192 -> 170 | X8: ='Cost model'!M193 -> 210 | Z8: ='Cost model'!M206 -> 110 | AA8: ='Cost model'!M207 -> 140 | AB8: ='Cost model'!M208 -> 170
A9: XXL | B9: ='Cost model'!M119 -> 145 | C9: ='Cost model'!M120 -> 235 | D9: ='Cost model'!M121 -> 285 | F9: ='Cost model'!M134 -> 135 | G9: ='Cost model'!M135 -> 240 | H9: ='Cost model'!M136 -> 280 | J9: ='Cost model'!M149 -> 155 | K9: ='Cost model'!M150 -> 265 | L9: ='Cost model'!M151 -> 320 | N9: ='Cost model'!M164 -> 195 | O9: ='Cost model'!M165 -> 325 | P9: ='Cost model'!M166 -> 390 | R9: ='Cost model'!M179 -> 135 | S9: ='Cost model'!M180 -> 150 | T9: ='Cost model'!M181 -> 230 | V9: ='Cost model'!M194 -> 170 | W9: ='Cost model'!M195 -> 285 | X9: ='Cost model'!M196 -> 345 | Z9: ='Cost model'!M209 -> 145 | AA9: ='Cost model'!M210 -> 240 | AB9: ='Cost model'!M211 -> 295
A11: Priority | B11: From QLD | F11: From VIC | J11: From SA | N11: From WA | R11: From NSW | V11: From TAS | Z11: From ACT
A12: Freight Size | B12: Metro | C12: Metro Outer | D12: Regional | F12: Metro | G12: Metro Outer | H12: Regional | J12: Metro | K12: Metro Outer | L12: Regional | N12: Metro | O12: Metro Outer | P12: Regional | R12: Metro | S12: Metro Outer | T12: Regional | V12: Metro | W12: Metro Outer | X12: Regional | Z12: Metro | AA12: Metro Outer | AB12: Regional
A13: Small | B13: ='Cost model'!N107 -> 17.5 | C13: ='Cost model'!N108 -> 21.5 | D13: ='Cost model'!N109 -> 25.5 | F13: ='Cost model'!N122 -> 18.5 | G13: ='Cost model'!N123 -> 22.5 | H13: ='Cost model'!N124 -> 29.5 | J13: ='Cost model'!N137 -> 18.5 | K13: ='Cost model'!N138 -> 22.5 | L13: ='Cost model'!N139 -> 26.5 | N13: ='Cost model'!N152 -> 18.5 | O13: ='Cost model'!N153 -> 21.5 | P13: ='Cost model'!N154 -> 27.5 | R13: ='Cost model'!N167 -> 13.5 | S13: ='Cost model'!N168 -> 18.5 | T13: ='Cost model'!N169 -> 25.5 | V13: ='Cost model'!N182 -> 19.5 | W13: ='Cost model'!N183 -> 23.5 | X13: ='Cost model'!N184 -> 35 | Z13: ='Cost model'!N197 -> 27.5 | AA13: ='Cost model'!N198 -> 27.5 | AB13: ='Cost model'!N199 -> 35
A14: Medium | B14: ='Cost model'!N110 -> 55 | C14: ='Cost model'!N111 -> 60 | D14: ='Cost model'!N112 -> 65 | F14: ='Cost model'!N125 -> 55 | G14: ='Cost model'!N126 -> 60 | H14: ='Cost model'!N127 -> 65 | J14: ='Cost model'!N140 -> 55 | K14: ='Cost model'!N141 -> 65 | L14: ='Cost model'!N142 -> 70 | N14: ='Cost model'!N155 -> 65 | O14: ='Cost model'!N156 -> 80 | P14: ='Cost model'!N157 -> 85 | R14: ='Cost model'!N170 -> 35 | S14: ='Cost model'!N171 -> 55 | T14: ='Cost model'!N172 -> 60 | V14: ='Cost model'!N185 -> 65 | W14: ='Cost model'!N186 -> 80 | X14: ='Cost model'!N187 -> 85 | Z14: ='Cost model'!N200 -> 60 | AA14: ='Cost model'!N201 -> 70 | AB14: ='Cost model'!N202 -> 85
A15: Large | B15: ='Cost model'!N113 -> 90 | C15: ='Cost model'!N114 -> 110 | D15: ='Cost model'!N115 -> 145 | F15: ='Cost model'!N128 -> 90 | G15: ='Cost model'!N129 -> 105 | H15: ='Cost model'!N130 -> 135 | J15: ='Cost model'!N143 -> 95 | K15: ='Cost model'!N144 -> 115 | L15: ='Cost model'!N145 -> 160 | N15: ='Cost model'!N158 -> 125 | O15: ='Cost model'!N159 -> 135 | P15: ='Cost model'!N160 -> 185 | R15: ='Cost model'!N173 -> 85 | S15: ='Cost model'!N174 -> 95 | T15: ='Cost model'!N175 -> 105 | V15: ='Cost model'!N188 -> 110 | W15: ='Cost model'!N189 -> 115 | X15: ='Cost model'!N190 -> 170 | Z15: ='Cost model'!N203 -> 90 | AA15: ='Cost model'!N204 -> 105 | AB15: ='Cost model'!N205 -> 145
A16: XL | B16: ='Cost model'!N116 -> 145 | C16: ='Cost model'!N117 -> 165 | D16: ='Cost model'!N118 -> 220 | F16: ='Cost model'!N131 -> 115 | G16: ='Cost model'!N132 -> 175 | H16: ='Cost model'!N133 -> 195 | J16: ='Cost model'!N146 -> 140 | K16: ='Cost model'!N147 -> 180 | L16: ='Cost model'!N148 -> 230 | N16: ='Cost model'!N161 -> 175 | O16: ='Cost model'!N162 -> 225 | P16: ='Cost model'!N163 -> 290 | R16: ='Cost model'!N176 -> 115 | S16: ='Cost model'!N177 -> 135 | T16: ='Cost model'!N178 -> 175 | V16: ='Cost model'!N191 -> 160 | W16: ='Cost model'!N192 -> 205 | X16: ='Cost model'!N193 -> 255 | Z16: ='Cost model'!N206 -> 135 | AA16: ='Cost model'!N207 -> 170 | AB16: ='Cost model'!N208 -> 205
A17: XXL | B17: ='Cost model'!N119 -> 175 | F17: ='Cost model'!N134 -> 165 | J17: ='Cost model'!N149 -> 190 | N17: ='Cost model'!N164 -> 235 | R17: ='Cost model'!N179 -> 165 | S17: ='Cost model'!N180 -> 180 | T17: ='Cost model'!N181 -> 280 | V17: ='Cost model'!N194 -> 205 | Z17: ='Cost model'!N209 -> 175
A19: Delivery time frames for NSW Orders
A21: Standard | B21: From QLD | F21: From VIC | J21: From SA | N21: From WA | R21: From NSW | V21: From TAS | Z21: From ACT
A22: Freight Size | B22: Metro | C22: Metro Outer | D22: Regional | F22: Metro | G22: Metro Outer | H22: Regional | J22: Metro | K22: Metro Outer | L22: Regional | N22: Metro | O22: Metro Outer | P22: Regional | R22: Metro | S22: Metro Outer | T22: Regional | V22: Metro | W22: Metro Outer | X22: Regional | Z22: Metro | AA22: Metro Outer | AB22: Regional
A23: Small | B23: 1-2 Days | C23: 1-3 Days | D23: 2-5 Days | F23: 1-2 Days | G23: 1-3 Days | H23: 2-5 Days | J23: 2-5 Days | K23: 2-5 Days | L23: 2-5 Days | N23: 7-10 Days | O23: 7-10 Days | P23: 7-10 Days | R23: 1-2 Days | S23: 1-3 Days | T23: 2-5 Days | V23: 7-14 Days | W23: 7-14 Days | X23: 7-14 Days | Z23: 7-14 Days | AA23: 7-14 Days | AB23: 7-14 Days
A24: Medium | B24: 1-2 Days | C24: 1-3 Days | D24: 2-5 Days | F24: 1-2 Days | G24: 1-3 Days | H24: 2-5 Days | J24: 2-5 Days | K24: 2-5 Days | L24: 2-5 Days | N24: 7-10 Days | O24: 7-10 Days | P24: 7-10 Days | R24: 1-2 Days | S24: 1-3 Days | T24: 2-5 Days | V24: 7-14 Days | W24: 7-14 Days | X24: 7-14 Days | Z24: 7-14 Days | AA24: 7-14 Days | AB24: 7-14 Days
A25: Large | B25: 1-2 Days | C25: 1-3 Days | D25: 3-7 Days | F25: 1-2 Days | G25: 1-3 Days | H25: 3-7 Days | J25: 3-7 Days | K25: 3-7 Days | L25: 5-10 Days | N25: 7-10 Days | O25: 7-10 Days | P25: 7-10 Days | R25: 1-2 Days | S25: 1-3 Days | T25: 3-7 Days | V25: 7-14 Days | W25: 7-14 Days | X25: 7-14 Days | Z25: 7-14 Days | AA25: 7-14 Days | AB25: 7-14 Days
A26: XL | B26: 2-5 Days | C26: 2-5 Days | D26: 5-10 Days | F26: 2-5 Days | G26: 2-5 Days | H26: 5-10 Days | J26: 5-10 Days | K26: 5-10 Days | L26: 5-10 Days | N26: 7-10 Days | O26: 7-10 Days | P26: 7-10 Days | R26: 2-5 Days | S26: 2-5 Days | T26: 5-10 Days | V26: 7-14 Days | W26: 7-14 Days | X26: 7-14 Days | Z26: 7-14 Days | AA26: 7-14 Days | AB26: 7-14 Days
A27: XXL | B27: 2-5 Days | C27: 1-3 Days | D27: 2-7 Days | F27: 2-5 Days | G27: 1-3 Days | H27: 2-7 Days | J27: 5-10 Days | K27: 3-7 Days | L27: 5-10 Days | N27: 7-10 Days | O27: 7-10 Days | P27: 7-14 Days | R27: 2-5 Days | S27: 2-5 Days | T27: 5-10 Days | V27: 7-14 Days | W27: 7-14 Days | X27: 7-14 Days | Z27: 7-14 Days | AA27: 7-14 Days | AB27: 7-14 Days
A29: Priority | B29: From QLD | F29: From VIC | J29: From SA | N29: From WA | R29: From NSW | V29: From TAS | Z29: From ACT
A30: Freight Size | B30: Metro | C30: Metro Outer | D30: Regional | F30: Metro | G30: Metro Outer | H30: Regional | J30: Metro | K30: Metro Outer | L30: Regional | N30: Metro | O30: Metro Outer | P30: Regional | R30: Metro | S30: Metro Outer | T30: Regional | V30: Metro | W30: Metro Outer | X30: Regional | Z30: Metro | AA30: Metro Outer | AB30: Regional
A31: Small | B31: 1-2 Days | C31: 1-2 Days | D31: 1-3 Days | F31: 1-2 Days | G31: 1-2 Days | H31: 1-3 Days | J31: 1-2 Days | K31: 1-2 Days | L31: 2-5 Days | N31: 1-2 Days | O31: 1-2 Days | P31: 2-5 Days | R31: 1-2 Days | S31: 1-2 Days | T31: 1-3 Days | V31: 1-2 Days | W31: 1-2 Days | X31: 2-5 Days | Z31: 1-2 Days | AA31: 1-2 Days | AB31: 2-5 Days
A32: Medium | B32: 1-2 Days | C32: 1-2 Days | D32: 1-3 Days | F32: 1-2 Days | G32: 1-2 Days | H32: 1-3 Days | J32: 1-2 Days | K32: 1-2 Days | L32: 2-5 Days | N32: 1-2 Days | O32: 1-2 Days | P32: 2-5 Days | R32: 1-2 Days | S32: 1-2 Days | T32: 1-3 Days | V32: 1-2 Days | W32: 1-2 Days | X32: 2-5 Days | Z32: 1-2 Days | AA32: 1-2 Days | AB32: 2-5 Days
A33: Large | B33: 1-2 Days | C33: 1-2 Days | D33: 2-7 Days | F33: 1-2 Days | G33: 1-2 Days | H33: 2-7 Days | J33: 2-5 Days | K33: 2-5 Days | L33: 5-10 Days | N33: 7-10 Days | O33: 7-10 Days | P33: 7-14 Days | R33: 1-2 Days | S33: 1-2 Days | T33: 2-7 Days | V33: 7-14 Days | W33: 7-14 Days | X33: 7-14 Days | Z33: 7-14 Days | AA33: 7-14 Days | AB33: 7-14 Days
A34: XL | B34: 1-3 Days | C34: 1-3 Days | D34: 2-7 Days | F34: 1-3 Days | G34: 1-3 Days | H34: 2-7 Days | J34: 3-7 Days | K34: 3-7 Days | L34: 5-10 Days | N34: 7-10 Days | O34: 7-10 Days | P34: 7-14 Days | R34: 1-3 Days | S34: 1-3 Days | T34: 2-7 Days | V34: 7-14 Days | W34: 7-14 Days | X34: 7-14 Days | Z34: 7-14 Days | AA34: 7-14 Days | AB34: 7-14 Days
A35: XXL | B35: 1-3 Days | F35: 1-3 Days | J35: 3-7 Days | N35: 7-10 Days | R35: 1-3 Days | S35: 1-3 Days | T35: 2-7 Days | V35: 7-14 Days | Z35: 7-14 Days

Sheet NT
A1: Freight Charges for NT Orders
A3: Standard | B3: From SA | F3: From VIC | J3: From WA | N3: From QLD | R3: From NSW | V3: From TAS | Z3: From ACT
A4: Freight Size | B4: Metro | C4: Metro Outer | D4: Regional | F4: Metro | G4: Metro Outer | H4: Regional | J4: Metro | K4: Metro Outer | L4: Regional | N4: Metro | O4: Metro Outer | P4: Regional | R4: Metro | S4: Metro Outer | T4: Regional | V4: Metro | W4: Metro Outer | X4: Regional | Z4: Metro | AA4: Metro Outer | AB4: Regional
A5: Small | B5: ='Cost model'!M212 -> 20.5 | C5: ='Cost model'!M213 -> 22.5 | D5: ='Cost model'!M214 -> 24.5 | F5: ='Cost model'!M227 -> 19.5 | G5: ='Cost model'!M228 -> 21.5 | H5: ='Cost model'!M229 -> 27.5 | J5: ='Cost model'!M242 -> 21.5 | K5: ='Cost model'!M243 -> 21.5 | L5: ='Cost model'!M244 -> 27.5 | N5: ='Cost model'!M257 -> 20.5 | O5: ='Cost model'!M258 -> 21.5 | P5: ='Cost model'!M259 -> 26.5 | R5: ='Cost model'!M272 -> 16.5 | S5: ='Cost model'!M273 -> 20.5 | T5: ='Cost model'!M274 -> 27.5 | V5: ='Cost model'!M287 -> 14.5 | W5: ='Cost model'!M288 -> 17.5 | X5: ='Cost model'!M289 -> 21.5 | Z5: ='Cost model'!M302 -> 14.5 | AA5: ='Cost model'!M303 -> 17.5 | AB5: ='Cost model'!M304 -> 21.5
A6: Medium | B6: ='Cost model'!M215 -> 60 | C6: ='Cost model'!M216 -> 65 | D6: ='Cost model'!M217 -> 70 | F6: ='Cost model'!M230 -> 55 | G6: ='Cost model'!M231 -> 65 | H6: ='Cost model'!M232 -> 80 | J6: ='Cost model'!M245 -> 60 | K6: ='Cost model'!M246 -> 65 | L6: ='Cost model'!M247 -> 75 | N6: ='Cost model'!M260 -> 55 | O6: ='Cost model'!M261 -> 60 | P6: ='Cost model'!M262 -> 70 | R6: ='Cost model'!M275 -> 70 | S6: ='Cost model'!M276 -> 70 | T6: ='Cost model'!M277 -> 80 | V6: ='Cost model'!M290 -> 45 | W6: ='Cost model'!M291 -> 55 | X6: ='Cost model'!M292 -> 60 | Z6: ='Cost model'!M305 -> 45 | AA6: ='Cost model'!M306 -> 55 | AB6: ='Cost model'!M307 -> 60
A7: Large | B7: ='Cost model'!M218 -> 95 | C7: ='Cost model'!M219 -> 100 | D7: ='Cost model'!M220 -> 135 | F7: ='Cost model'!M233 -> 95 | G7: ='Cost model'!M234 -> 105 | H7: ='Cost model'!M235 -> 145 | J7: ='Cost model'!M248 -> 100 | K7: ='Cost model'!M249 -> 110 | L7: ='Cost model'!M250 -> 150 | N7: ='Cost model'!M263 -> 90 | O7: ='Cost model'!M264 -> 105 | P7: ='Cost model'!M265 -> 140 | R7: ='Cost model'!M278 -> 90 | S7: ='Cost model'!M279 -> 105 | T7: ='Cost model'!M280 -> 145 | V7: ='Cost model'!M293 -> 85 | W7: ='Cost model'!M294 -> 95 | X7: ='Cost model'!M295 -> 130 | Z7: ='Cost model'!M308 -> 80 | AA7: ='Cost model'!M309 -> 95 | AB7: ='Cost model'!M310 -> 125
A8: XL | B8: ='Cost model'!M221 -> 150 | C8: ='Cost model'!M222 -> 185 | D8: ='Cost model'!M223 -> 225 | F8: ='Cost model'!M236 -> 155 | G8: ='Cost model'!M237 -> 195 | H8: ='Cost model'!M238 -> 250 | J8: ='Cost model'!M251 -> 165 | K8: ='Cost model'!M252 -> 205 | L8: ='Cost model'!M253 -> 255 | N8: ='Cost model'!M266 -> 150 | O8: ='Cost model'!M267 -> 190 | P8: ='Cost model'!M268 -> 240 | R8: ='Cost model'!M281 -> 155 | S8: ='Cost model'!M282 -> 195 | T8: ='Cost model'!M283 -> 245 | V8: ='Cost model'!M296 -> 135 | W8: ='Cost model'!M297 -> 175 | X8: ='Cost model'!M298 -> 220 | Z8: ='Cost model'!M311 -> 135 | AA8: ='Cost model'!M312 -> 175 | AB8: ='Cost model'!M313 -> 220
A9: XXL | B9: ='Cost model'!M224 -> 190 | C9: ='Cost model'!M225 -> 325 | D9: ='Cost model'!M226 -> 405 | F9: ='Cost model'!M239 -> 205 | G9: ='Cost model'!M240 -> 345 | H9: ='Cost model'!M241 -> 410 | J9: ='Cost model'!M254 -> 215 | K9: ='Cost model'!M255 -> 360 | L9: ='Cost model'!M256 -> 435 | N9: ='Cost model'!M269 -> 200 | O9: ='Cost model'!M270 -> 340 | P9: ='Cost model'!M271 -> 400 | R9: ='Cost model'!M284 -> 205 | S9: ='Cost model'!M285 -> 345 | T9: ='Cost model'!M286 -> 415 | V9: ='Cost model'!M299 -> 185 | W9: ='Cost model'!M300 -> 310 | X9: ='Cost model'!M301 -> 370 | Z9: ='Cost model'!M314 -> 180 | AA9: ='Cost model'!M315 -> 300 | AB9: ='Cost model'!M316 -> 360
A11: Priority | B11: From SA | F11: From VIC | J11: From WA | N11: From QLD | R11: From NSW | V11: From TAS | Z11: From ACT
A12: Freight Size | B12: Metro | C12: Metro Outer | D12: Regional | F12: Metro | G12: Metro Outer | H12: Regional | J12: Metro | K12: Metro Outer | L12: Regional | N12: Metro | O12: Metro Outer | P12: Regional | R12: Metro | S12: Metro Outer | T12: Regional | V12: Metro | W12: Metro Outer | X12: Regional | Z12: Metro | AA12: Metro Outer | AB12: Regional
A13: Small | B13: ='Cost model'!N212 -> 27.5 | C13: ='Cost model'!N213 -> 35 | D13: ='Cost model'!N214 -> 35 | F13: ='Cost model'!N227 -> 26.5 | G13: ='Cost model'!N228 -> 29.5 | H13: ='Cost model'!N229 -> 40 | J13: ='Cost model'!N242 -> 29.5 | K13: ='Cost model'!N243 -> 29.5 | L13: ='Cost model'!N244 -> 40 | N13: ='Cost model'!N257 -> 27.5 | O13: ='Cost model'!N258 -> 29.5 | P13: ='Cost model'!N259 -> 40 | R13: ='Cost model'!N272 -> 22.5 | S13: ='Cost model'!N273 -> 27.5 | T13: ='Cost model'!N274 -> 40 | V13: ='Cost model'!N287 -> 19.5 | W13: ='Cost model'!N288 -> 23.5 | X13: ='Cost model'!N289 -> 29.5 | Z13: ='Cost model'!N302 -> 19.5 | AA13: ='Cost model'!N303 -> 23.5 | AB13: ='Cost model'!N304 -> 29.5
A14: Medium | B14: ='Cost model'!N215 -> 80 | C14: ='Cost model'!N216 -> 85 | D14: ='Cost model'!N217 -> 90 | F14: ='Cost model'!N230 -> 70 | G14: ='Cost model'!N231 -> 85 | H14: ='Cost model'!N232 -> 105 | J14: ='Cost model'!N245 -> 80 | K14: ='Cost model'!N246 -> 85 | L14: ='Cost model'!N247 -> 95 | N14: ='Cost model'!N260 -> 70 | O14: ='Cost model'!N261 -> 80 | P14: ='Cost model'!N262 -> 90 | R14: ='Cost model'!N275 -> 90 | S14: ='Cost model'!N276 -> 90 | T14: ='Cost model'!N277 -> 105 | V14: ='Cost model'!N290 -> 60 | W14: ='Cost model'!N291 -> 70 | X14: ='Cost model'!N292 -> 80 | Z14: ='Cost model'!N305 -> 60 | AA14: ='Cost model'!N306 -> 70 | AB14: ='Cost model'!N307 -> 80
A15: Large | B15: ='Cost model'!N218 -> 130 | C15: ='Cost model'!N219 -> 135 | D15: ='Cost model'!N220 -> 185 | F15: ='Cost model'!N233 -> 130 | G15: ='Cost model'!N234 -> 145 | H15: ='Cost model'!N235 -> 200 | J15: ='Cost model'!N248 -> 135 | K15: ='Cost model'!N249 -> 150 | L15: ='Cost model'!N250 -> 205 | N15: ='Cost model'!N263 -> 125 | O15: ='Cost model'!N264 -> 145 | P15: ='Cost model'!N265 -> 190 | R15: ='Cost model'!N278 -> 125 | S15: ='Cost model'!N279 -> 145 | T15: ='Cost model'!N280 -> 200 | V15: ='Cost model'!N293 -> 115 | W15: ='Cost model'!N294 -> 130 | X15: ='Cost model'!N295 -> 180 | Z15: ='Cost model'!N308 -> 110 | AA15: ='Cost model'!N309 -> 130 | AB15: ='Cost model'!N310 -> 170
A16: XL | B16: ='Cost model'!N221 -> 180 | C16: ='Cost model'!N222 -> 225 | D16: ='Cost model'!N223 -> 270 | F16: ='Cost model'!N236 -> 190 | G16: ='Cost model'!N237 -> 235 | H16: ='Cost model'!N238 -> 300 | J16: ='Cost model'!N251 -> 200 | K16: ='Cost model'!N252 -> 250 | L16: ='Cost model'!N253 -> 310 | N16: ='Cost model'!N266 -> 180 | O16: ='Cost model'!N267 -> 230 | P16: ='Cost model'!N268 -> 290 | R16: ='Cost model'!N281 -> 190 | S16: ='Cost model'!N282 -> 235 | T16: ='Cost model'!N283 -> 295 | V16: ='Cost model'!N296 -> 165 | W16: ='Cost model'!N297 -> 210 | X16: ='Cost model'!N298 -> 265 | Z16: ='Cost model'!N311 -> 165 | AA16: ='Cost model'!N312 -> 210 | AB16: ='Cost model'!N313 -> 265
A17: XXL | B17: ='Cost model'!N224 -> 230 | F17: ='Cost model'!N239 -> 250 | J17: ='Cost model'!N254 -> 260 | N17: ='Cost model'!N269 -> 240 | R17: ='Cost model'!N284 -> 250 | V17: ='Cost model'!N299 -> 225 | Z17: ='Cost model'!N314 -> 220
A19: Delivery time frames for NT Orders
A21: Standard | B21: From SA | F21: From VIC | J21: From WA | N21: From QLD | R21: From NSW | V21: From TAS | Z21: From ACT
A22: Freight Size | B22: Metro | C22: Metro Outer | D22: Regional | F22: Metro | G22: Metro Outer | H22: Regional | J22: Metro | K22: Metro Outer | L22: Regional | N22: Metro | O22: Metro Outer | P22: Regional | R22: Metro | S22: Metro Outer | T22: Regional | V22: Metro | W22: Metro Outer | X22: Regional | Z22: Metro | AA22: Metro Outer | AB22: Regional
A23: Small | B23: 1-2 Days | C23: 1-3 Days | D23: 2-5 Days | F23: 2-5 Days | G23: 3-7 Days | H23: 5-10 Days | J23: 2-5 Days | K23: 2-5 Days | L23: 3-7 Days | N23: 2-5 Days | O23: 2-5 Days | P23: 3-7 Days | R23: 2-5 Days | S23: 2-5 Days | T23: 3-7 Days | V23: 7-14 Days | W23: 7-14 Days | X23: 7-14 Days | Z23: 7-14 Days | AA23: 7-14 Days | AB23: 7-14 Days
A24: Medium | B24: 1-2 Days | C24: 1-3 Days | D24: 2-5 Days | F24: 2-5 Days | G24: 3-7 Days | H24: 5-10 Days | J24: 2-5 Days | K24: 2-5 Days | L24: 3-7 Days | N24: 2-5 Days | O24: 2-5 Days | P24: 3-7 Days | R24: 2-5 Days | S24: 2-5 Days | T24: 3-7 Days | V24: 7-14 Days | W24: 7-14 Days | X24: 7-14 Days | Z24: 7-14 Days | AA24: 7-14 Days | AB24: 7-14 Days
A25: Large | B25: 1-2 Days | C25: 1-3 Days | D25: 3-7 Days | F25: 3-7 Days | G25: 3-7 Days | H25: 5-10 Days | J25: 5-10 Days | K25: 5-10 Days | L25: 5-10 Days | N25: 5-10 Days | O25: 5-10 Days | P25: 5-10 Days | R25: 5-10 Days | S25: 5-10 Days | T25: 5-10 Days | V25: 7-14 Days | W25: 7-14 Days | X25: 7-14 Days | Z25: 7-14 Days | AA25: 7-14 Days | AB25: 7-14 Days
A26: XL | B26: 1-2 Days | C26: 1-3 Days | D26: 5-10 Days | F26: 5-10 Days | G26: 5-10 Days | H26: 5-10 Days | J26: 5-10 Days | K26: 5-10 Days | L26: 5-10 Days | N26: 5-10 Days | O26: 5-10 Days | P26: 5-10 Days | R26: 5-10 Days | S26: 5-10 Days | T26: 5-10 Days | V26: 7-14 Days | W26: 7-14 Days | X26: 7-14 Days | Z26: 7-14 Days | AA26: 7-14 Days | AB26: 7-14 Days
A27: XXL | B27: 1-2 Days | F27: 5-10 Days | J27: 5-10 Days | N27: 5-10 Days | R27: 5-10 Days | V27: 7-14 Days | W27: 7-14 Days | X27: 7-14 Days | Z27: 7-14 Days | AA27: 7-14 Days | AB27: 7-14 Days
A29: Priority | B29: From SA | F29: From VIC | J29: From WA | N29: From QLD | R29: From NSW | V29: From TAS | Z29: From ACT
A30: Freight Size | B30: Metro | C30: Metro Outer | D30: Regional | F30: Metro | G30: Metro Outer | H30: Regional | J30: Metro | K30: Metro Outer | L30: Regional | N30: Metro | O30: Metro Outer | P30: Regional | R30: Metro | S30: Metro Outer | T30: Regional | V30: Metro | W30: Metro Outer | X30: Regional | Z30: Metro | AA30: Metro Outer | AB30: Regional
A31: Small | B31: 1-3 Days | C31: 2-5 Days | D31: 3-7 Days | F31: 1-3 Days | G31: 2-5 Days | H31: 3-7 Days | J31: 1-3 Days | K31: 3-7 Days | L31: 3-7 Days | N31: 1-2 Days | O31: 1-2 Days | P31: 2-5 Days | R31: 1-2 Days | S31: 1-2 Days | T31: 2-5 Days | V31: 1-2 Days | W31: 1-2 Days | X31: 2-5 Days | Z31: 1-2 Days | AA31: 1-2 Days | AB31: 2-5 Days
A32: Medium | B32: 1-3 Days | C32: 2-5 Days | D32: 3-7 Days | F32: 1-3 Days | G32: 2-5 Days | H32: 3-7 Days | J32: 1-3 Days | K32: 3-7 Days | L32: 3-7 Days | N32: 1-2 Days | O32: 1-2 Days | P32: 2-5 Days | R32: 1-2 Days | S32: 1-2 Days | T32: 2-5 Days | V32: 1-2 Days | W32: 1-2 Days | X32: 2-5 Days | Z32: 1-2 Days | AA32: 1-2 Days | AB32: 2-5 Days
A33: Large | B33: 1-3 Days | C33: 2-5 Days | D33: 3-7 Days | F33: 1-3 Days | G33: 2-5 Days | H33: 3-7 Days | J33: 3-7 Days | K33: 3-7 Days | L33: 5-10 Days | N33: 7-14 Days | O33: 7-14 Days | P33: 7-14 Days | R33: 7-14 Days | S33: 7-14 Days | T33: 7-14 Days | V33: 7-14 Days | W33: 7-14 Days | X33: 7-14 Days | Z33: 7-14 Days | AA33: 7-14 Days | AB33: 7-14 Days
A34: XL | V34: 7-14 Days | W34: 7-14 Days | X34: 7-14 Days | Z34: 7-14 Days | AA34: 7-14 Days | AB34: 7-14 Days
A35: XXL | V35: 7-14 Days | Z35: 7-14 Days

Sheet QLD
A1: Freight Charges for QLD Orders
A3: Standard | B3: From QLD | F3: From VIC | J3: From SA | N3: From NSW | R3: From TAS | V3: From ACT | Z3: From WA
A4: Freight Size | B4: Metro | C4: Metro Outer | D4: Regional | F4: Metro | G4: Metro Outer | H4: Regional | J4: Metro | K4: Metro Outer | L4: Regional | N4: Metro | O4: Metro Outer | P4: Regional | R4: Metro | S4: Metro Outer | T4: Regional | V4: Metro | W4: Metro Outer | X4: Regional | Z4: Metro | AA4: Metro Outer | AB4: Regional
A5: Small | B5: ='Cost model'!M317 -> 10.5 | C5: ='Cost model'!M318 -> 14.5 | D5: ='Cost model'!M319 -> 16.5 | F5: ='Cost model'!M332 -> 16.5 | G5: ='Cost model'!M333 -> 18.5 | H5: ='Cost model'!M334 -> 20.5 | J5: ='Cost model'!M347 -> 13.5 | K5: ='Cost model'!M348 -> 17.5 | L5: ='Cost model'!M349 -> 20.5 | N5: ='Cost model'!M362 -> 10.5 | O5: ='Cost model'!M363 -> 15.5 | P5: ='Cost model'!M364 -> 16.5 | R5: ='Cost model'!M377 -> 15.5 | S5: ='Cost model'!M378 -> 18.5 | T5: ='Cost model'!M379 -> 23.5 | V5: ='Cost model'!M392 -> 13.5 | W5: ='Cost model'!M393 -> 18.5 | X5: ='Cost model'!M394 -> 20.5 | Z5: ='Cost model'!M407 -> 12.5 | AA5: ='Cost model'!M408 -> 21.5 | AB5: ='Cost model'!M409 -> 21.5
A6: Medium | B6: ='Cost model'!M320 -> 24.5 | C6: ='Cost model'!M321 -> 40 | D6: ='Cost model'!M322 -> 50 | F6: ='Cost model'!M335 -> 45 | G6: ='Cost model'!M336 -> 50 | H6: ='Cost model'!M337 -> 60 | J6: ='Cost model'!M350 -> 50 | K6: ='Cost model'!M351 -> 55 | L6: ='Cost model'!M352 -> 60 | N6: ='Cost model'!M365 -> 45 | O6: ='Cost model'!M366 -> 55 | P6: ='Cost model'!M367 -> 60 | R6: ='Cost model'!M380 -> 55 | S6: ='Cost model'!M381 -> 65 | T6: ='Cost model'!M382 -> 90 | V6: ='Cost model'!M395 -> 50 | W6: ='Cost model'!M396 -> 60 | X6: ='Cost model'!M397 -> 60 | Z6: ='Cost model'!M410 -> 45 | AA6: ='Cost model'!M411 -> 50 | AB6: ='Cost model'!M412 -> 60
A7: Large | B7: ='Cost model'!M323 -> 60 | C7: ='Cost model'!M324 -> 85 | D7: ='Cost model'!M325 -> 110 | F7: ='Cost model'!M338 -> 85 | G7: ='Cost model'!M339 -> 85 | H7: ='Cost model'!M340 -> 125 | J7: ='Cost model'!M353 -> 75 | K7: ='Cost model'!M354 -> 90 | L7: ='Cost model'!M355 -> 120 | N7: ='Cost model'!M368 -> 75 | O7: ='Cost model'!M369 -> 100 | P7: ='Cost model'!M370 -> 120 | R7: ='Cost model'!M383 -> 85 | S7: ='Cost model'!M384 -> 105 | T7: ='Cost model'!M385 -> 140 | V7: ='Cost model'!M398 -> 80 | W7: ='Cost model'!M399 -> 90 | X7: ='Cost model'!M400 -> 120 | Z7: ='Cost model'!M413 -> 80 | AA7: ='Cost model'!M414 -> 90 | AB7: ='Cost model'!M415 -> 125
A8: XL | B8: ='Cost model'!M326 -> 110 | C8: ='Cost model'!M327 -> 130 | D8: ='Cost model'!M328 -> 175 | F8: ='Cost model'!M341 -> 130 | G8: ='Cost model'!M342 -> 155 | H8: ='Cost model'!M343 -> 205 | J8: ='Cost model'!M356 -> 125 | K8: ='Cost model'!M357 -> 175 | L8: ='Cost model'!M358 -> 210 | N8: ='Cost model'!M371 -> 130 | O8: ='Cost model'!M372 -> 165 | P8: ='Cost model'!M373 -> 215 | R8: ='Cost model'!M386 -> 150 | S8: ='Cost model'!M387 -> 195 | T8: ='Cost model'!M388 -> 255 | V8: ='Cost model'!M401 -> 130 | W8: ='Cost model'!M402 -> 165 | X8: ='Cost model'!M403 -> 210 | Z8: ='Cost model'!M416 -> 130 | AA8: ='Cost model'!M417 -> 165 | AB8: ='Cost model'!M418 -> 210
A9: XXL | B9: ='Cost model'!M329 -> 135 | C9: ='Cost model'!M330 -> 180 | D9: ='Cost model'!M331 -> 280 | F9: ='Cost model'!M344 -> 170 | G9: ='Cost model'!M345 -> 280 | H9: ='Cost model'!M346 -> 340 | J9: ='Cost model'!M359 -> 175 | K9: ='Cost model'!M360 -> 290 | L9: ='Cost model'!M361 -> 345 | N9: ='Cost model'!M374 -> 180 | O9: ='Cost model'!M375 -> 285 | P9: ='Cost model'!M376 -> 350 | R9: ='Cost model'!M389 -> 200 | S9: ='Cost model'!M390 -> 330 | T9: ='Cost model'!M391 -> 400 | V9: ='Cost model'!M404 -> 175 | W9: ='Cost model'!M405 -> 295 | X9: ='Cost model'!M406 -> 350 | Z9: ='Cost model'!M419 -> 175 | AA9: ='Cost model'!M420 -> 290 | AB9: ='Cost model'!M421 -> 350
A11: Priority | B11: From QLD | F11: From VIC | J11: From SA | N11: From NSW | R11: From TAS | V11: From ACT | Z11: From WA
A12: Freight Size | B12: Metro | C12: Metro Outer | D12: Regional | F12: Metro | G12: Metro Outer | H12: Regional | J12: Metro | K12: Metro Outer | L12: Regional | N12: Metro | O12: Metro Outer | P12: Regional | R12: Metro | S12: Metro Outer | T12: Regional | V12: Metro | W12: Metro Outer | X12: Regional | Z12: Metro | AA12: Metro Outer | AB12: Regional
A13: Small | B13: ='Cost model'!N317 -> 15.5 | C13: ='Cost model'!N318 -> 19.5 | D13: ='Cost model'!N319 -> 22.5 | F13: ='Cost model'!N332 -> 22.5 | G13: ='Cost model'!N333 -> 25.5 | H13: ='Cost model'!N334 -> 27.5 | J13: ='Cost model'!N347 -> 18.5 | K13: ='Cost model'!N348 -> 23.5 | L13: ='Cost model'!N349 -> 27.5 | N13: ='Cost model'!N362 -> 15.5 | O13: ='Cost model'!N363 -> 21.5 | P13: ='Cost model'!N364 -> 22.5 | R13: ='Cost model'!N377 -> 21.5 | S13: ='Cost model'!N378 -> 25.5 | T13: ='Cost model'!N379 -> 35 | V13: ='Cost model'!N392 -> 18.5 | W13: ='Cost model'!N393 -> 25.5 | X13: ='Cost model'!N394 -> 27.5 | Z13: ='Cost model'!N407 -> 17.5 | AA13: ='Cost model'!N408 -> 29.5 | AB13: ='Cost model'!N409 -> 29.5
A14: Medium | B14: ='Cost model'!N320 -> 35 | C14: ='Cost model'!N321 -> 55 | D14: ='Cost model'!N322 -> 65 | F14: ='Cost model'!N335 -> 60 | G14: ='Cost model'!N336 -> 65 | H14: ='Cost model'!N337 -> 80 | J14: ='Cost model'!N350 -> 65 | K14: ='Cost model'!N351 -> 70 | L14: ='Cost model'!N352 -> 80 | N14: ='Cost model'!N365 -> 60 | O14: ='Cost model'!N366 -> 70 | P14: ='Cost model'!N367 -> 80 | R14: ='Cost model'!N380 -> 70 | S14: ='Cost model'!N381 -> 85 | T14: ='Cost model'!N382 -> 115 | V14: ='Cost model'!N395 -> 65 | W14: ='Cost model'!N396 -> 80 | X14: ='Cost model'!N397 -> 80 | Z14: ='Cost model'!N410 -> 60 | AA14: ='Cost model'!N411 -> 65 | AB14: ='Cost model'!N412 -> 80
A15: Large | B15: ='Cost model'!N323 -> 85 | C15: ='Cost model'!N324 -> 115 | D15: ='Cost model'!N325 -> 150 | F15: ='Cost model'!N338 -> 115 | G15: ='Cost model'!N339 -> 115 | H15: ='Cost model'!N340 -> 170 | J15: ='Cost model'!N353 -> 105 | K15: ='Cost model'!N354 -> 125 | L15: ='Cost model'!N355 -> 165 | N15: ='Cost model'!N368 -> 105 | O15: ='Cost model'!N369 -> 135 | P15: ='Cost model'!N370 -> 165 | R15: ='Cost model'!N383 -> 115 | S15: ='Cost model'!N384 -> 145 | T15: ='Cost model'!N385 -> 190 | V15: ='Cost model'!N398 -> 110 | W15: ='Cost model'!N399 -> 125 | X15: ='Cost model'!N400 -> 165 | Z15: ='Cost model'!N413 -> 110 | AA15: ='Cost model'!N414 -> 125 | AB15: ='Cost model'!N415 -> 170
A16: XL | B16: ='Cost model'!N326 -> 135 | C16: ='Cost model'!N327 -> 160 | D16: ='Cost model'!N328 -> 210 | F16: ='Cost model'!N341 -> 160 | G16: ='Cost model'!N342 -> 190 | H16: ='Cost model'!N343 -> 250 | J16: ='Cost model'!N356 -> 150 | K16: ='Cost model'!N357 -> 210 | L16: ='Cost model'!N358 -> 255 | N16: ='Cost model'!N371 -> 160 | O16: ='Cost model'!N372 -> 200 | P16: ='Cost model'!N373 -> 260 | R16: ='Cost model'!N386 -> 180 | S16: ='Cost model'!N387 -> 235 | T16: ='Cost model'!N388 -> 310 | V16: ='Cost model'!N401 -> 160 | W16: ='Cost model'!N402 -> 200 | X16: ='Cost model'!N403 -> 255 | Z16: ='Cost model'!N416 -> 160 | AA16: ='Cost model'!N417 -> 200 | AB16: ='Cost model'!N418 -> 255
A17: XXL | B17: ='Cost model'!N329 -> 165 | C17: ='Cost model'!N330 -> 220 | D17: ='Cost model'!N331 -> 340 | F17: ='Cost model'!N344 -> 205 | J17: ='Cost model'!N359 -> 210 | N17: ='Cost model'!N374 -> 220 | R17: ='Cost model'!N389 -> 240 | V17: ='Cost model'!N404 -> 210 | Z17: ='Cost model'!N419 -> 210
A19: Delivery time frames for QLD Orders
A21: Standard | B21: From QLD | F21: From VIC | J21: From SA | N21: From NSW | R21: From TAS | V21: From ACT | Z21: From WA
A22: Freight Size | B22: Metro | C22: Metro Outer | D22: Regional | F22: Metro | G22: Metro Outer | H22: Regional | J22: Metro | K22: Metro Outer | L22: Regional | N22: Metro | O22: Metro Outer | P22: Regional | R22: Metro | S22: Metro Outer | T22: Regional | V22: Metro | W22: Metro Outer | X22: Regional | Z22: Metro | AA22: Metro Outer | AB22: Regional
A23: Small | B23: 1-3 Days | C23: 1-3 Days | D23: 2-5 Days | F23: 2-5 Days | G23: 2-5 Days | H23: 3-7 Days | J23: 2-5 Days | K23: 2-5 Days | L23: 2-5 Days | N23: 2-5 Days | O23: 2-5 Days | P23: 3-7 Days | R23: 7-14 Days | S23: 7-14 Days | T23: 7-14 Days | V23: 7-14 Days | W23: 7-14 Days | X23: 7-14 Days | Z23: 7-14 Days | AA23: 7-14 Days | AB23: 7-14 Days
A24: Medium | B24: 1-3 Days | C24: 1-3 Days | D24: 2-5 Days | F24: 2-5 Days | G24: 2-5 Days | H24: 3-7 Days | J24: 2-5 Days | K24: 2-5 Days | L24: 2-5 Days | N24: 2-5 Days | O24: 2-5 Days | P24: 3-7 Days | R24: 7-14 Days | S24: 7-14 Days | T24: 7-14 Days | V24: 7-14 Days | W24: 7-14 Days | X24: 7-14 Days | Z24: 7-14 Days | AA24: 7-14 Days | AB24: 7-14 Days
A25: Large | B25: 1-3 Days | C25: 1-3 Days | D25: 3-7 Days | F25: 3-7 Days | G25: 3-7 Days | H25: 5-10 Days | J25: 3-7 Days | K25: 3-7 Days | L25: 5-10 Days | N25: 3-7 Days | O25: 3-7 Days | P25: 5-10 Days | R25: 7-14 Days | S25: 7-14 Days | T25: 7-14 Days | V25: 7-14 Days | W25: 7-14 Days | X25: 7-14 Days | Z25: 7-14 Days | AA25: 7-14 Days | AB25: 7-14 Days
A26: XL | B26: 1-3 Days | C26: 1-3 Days | D26: 5-10 Days | F26: 5-10 Days | G26: 5-10 Days | H26: 5-10 Days | J26: 5-10 Days | K26: 5-10 Days | L26: 5-10 Days | N26: 5-10 Days | O26: 5-10 Days | P26: 5-10 Days | R26: 7-14 Days | S26: 7-14 Days | T26: 7-14 Days | V26: 7-14 Days | W26: 7-14 Days | X26: 7-14 Days | Z26: 7-14 Days | AA26: 7-14 Days | AB26: 7-14 Days
A27: XXL | B27: 1-3 Days | C27: 1-3 Days | D27: 5-10 Days | F27: 5-10 Days | G27: 3-7 Days | H27: 5-10 Days | J27: 5-10 Days | K27: 3-7 Days | L27: 5-10 Days | N27: 5-10 Days | O27: 3-7 Days | P27: 5-10 Days | R27: 7-14 Days | S27: 7-14 Days | T27: 7-14 Days | V27: 7-14 Days | W27: 7-14 Days | X27: 7-14 Days | Z27: 7-14 Days | AA27: 7-14 Days | AB27: 7-14 Days
A29: Priority | B29: From QLD | F29: From VIC | J29: From SA | N29: From NSW | R29: From TAS | V29: From ACT | Z29: From WA
A30: Freight Size | B30: Metro | C30: Metro Outer | D30: Regional | F30: Metro | G30: Metro Outer | H30: Regional | J30: Metro | K30: Metro Outer | L30: Regional | N30: Metro | O30: Metro Outer | P30: Regional | R30: Metro | S30: Metro Outer | T30: Regional | V30: Metro | W30: Metro Outer | X30: Regional | Z30: Metro | AA30: Metro Outer | AB30: Regional
A31: Small | B31: 1-2 Days | C31: 1-2 Days | D31: 1-3 Days | F31: 1-2 Days | G31: 1-2 Days | H31: 2-5 Days | J31: 1-2 Days | K31: 1-2 Days | L31: 2-5 Days | N31: 1-2 Days | O31: 1-2 Days | P31: 2-5 Days | R31: 1-2 Days | S31: 1-2 Days | T31: 2-5 Days | V31: 1-2 Days | W31: 1-2 Days | X31: 2-5 Days | Z31: 1-2 Days | AA31: 1-2 Days | AB31: 2-5 Days
A32: Medium | B32: 1-2 Days | C32: 1-2 Days | D32: 1-3 Days | F32: 1-2 Days | G32: 1-2 Days | H32: 2-5 Days | J32: 1-2 Days | K32: 1-2 Days | L32: 2-5 Days | N32: 1-2 Days | O32: 1-2 Days | P32: 2-5 Days | R32: 1-2 Days | S32: 1-2 Days | T32: 2-5 Days | V32: 1-2 Days | W32: 1-2 Days | X32: 2-5 Days | Z32: 1-2 Days | AA32: 1-2 Days | AB32: 2-5 Days
A33: Large | B33: 1-2 Days | C33: 1-2 Days | D33: 2-7 Days | F33: 2-5 Days | G33: 2-5 Days | H33: 5-10 Days | J33: 2-5 Days | K33: 2-5 Days | L33: 5-10 Days | N33: 2-5 Days | O33: 2-5 Days | P33: 5-10 Days | R33: 7-14 Days | S33: 7-14 Days | T33: 7-14 Days | V33: 7-14 Days | W33: 7-14 Days | X33: 7-14 Days | Z33: 7-14 Days | AA33: 7-14 Days | AB33: 7-14 Days
A34: XL | B34: 1-2 Days | C34: 1-2 Days | D34: 2-7 Days | F34: 3-7 Days | G34: 3-7 Days | H34: 5-10 Days | J34: 3-7 Days | K34: 3-7 Days | L34: 5-10 Days | N34: 3-7 Days | O34: 3-7 Days | P34: 5-10 Days | R34: 7-14 Days | S34: 7-14 Days | T34: 7-14 Days | V34: 7-14 Days | W34: 7-14 Days | X34: 7-14 Days | Z34: 7-14 Days | AA34: 7-14 Days | AB34: 7-14 Days
A35: XXL | B35: 1-2 Days | C35: 1-2 Days | D35: 2-7 Days | F35: 3-7 Days | J35: 3-7 Days | N35: 3-7 Days | R35: 7-14 Days | V35: 7-14 Days | Z35: 7-14 Days

Sheet SA
A1: Freight Charges for SA Orders
